[2025-06-03T19:03:43.275+0000] {local_task_job_runner.py:120} INFO - ::group::Pre task execution logs
[2025-06-03T19:03:43.290+0000] {taskinstance.py:2076} INFO - Dependencies all met for dep_context=non-requeueable deps ti=<TaskInstance: f1_data_extraction_pipeline.load_data_to_postgres manual__2025-06-03T19:03:35+00:00 [queued]>
[2025-06-03T19:03:43.293+0000] {taskinstance.py:2076} INFO - Dependencies all met for dep_context=requeueable deps ti=<TaskInstance: f1_data_extraction_pipeline.load_data_to_postgres manual__2025-06-03T19:03:35+00:00 [queued]>
[2025-06-03T19:03:43.293+0000] {taskinstance.py:2306} INFO - Starting attempt 1 of 1
[2025-06-03T19:03:43.298+0000] {taskinstance.py:2330} INFO - Executing <Task(PythonOperator): load_data_to_postgres> on 2025-06-03 19:03:35+00:00
[2025-06-03T19:03:43.303+0000] {standard_task_runner.py:90} INFO - Running: ['***', 'tasks', 'run', 'f1_data_extraction_pipeline', 'load_data_to_postgres', 'manual__2025-06-03T19:03:35+00:00', '--job-id', '11', '--raw', '--subdir', 'DAGS_FOLDER/f1_pipeline.py', '--cfg-path', '/tmp/tmpvl1ewdlu']
[2025-06-03T19:03:43.310+0000] {standard_task_runner.py:91} INFO - Job 11: Subtask load_data_to_postgres
[2025-06-03T19:03:43.403+0000] {logging_mixin.py:188} WARNING - /home/***/.local/lib/python3.12/site-packages/***/task/task_runner/standard_task_runner.py:61 DeprecationWarning: This process (pid=267) is multi-threaded, use of fork() may lead to deadlocks in the child.
[2025-06-03T19:03:43.405+0000] {standard_task_runner.py:63} INFO - Started process 268 to run task
[2025-06-03T19:03:43.423+0000] {task_command.py:426} INFO - Running <TaskInstance: f1_data_extraction_pipeline.load_data_to_postgres manual__2025-06-03T19:03:35+00:00 [running]> on host 8ce6f59a219c
[2025-06-03T19:03:43.461+0000] {taskinstance.py:2648} INFO - Exporting env vars: AIRFLOW_CTX_DAG_OWNER='***' AIRFLOW_CTX_DAG_ID='f1_data_extraction_pipeline' AIRFLOW_CTX_TASK_ID='load_data_to_postgres' AIRFLOW_CTX_EXECUTION_DATE='2025-06-03T19:03:35+00:00' AIRFLOW_CTX_TRY_NUMBER='1' AIRFLOW_CTX_DAG_RUN_ID='manual__2025-06-03T19:03:35+00:00'
[2025-06-03T19:03:43.461+0000] {taskinstance.py:430} INFO - ::endgroup::
[2025-06-03T19:03:43.466+0000] {logging_mixin.py:188} INFO - Début du chargement en base de données pour l'année 2024.
[2025-06-03T19:03:43.466+0000] {logging_mixin.py:188} INFO - Fichier CSV non trouvé : /opt/***/data/processed/2024/circuits_info.csv. Chargement sauté pour la table circuits.
[2025-06-03T19:03:43.479+0000] {base.py:84} INFO - Using connection ID 'f1_postgres_db' for task execution.
[2025-06-03T19:03:43.488+0000] {logging_mixin.py:188} INFO - Données de /opt/***/data/processed/2024/drivers.csv chargées avec succès dans la table drivers.
[2025-06-03T19:03:43.493+0000] {base.py:84} INFO - Using connection ID 'f1_postgres_db' for task execution.
[2025-06-03T19:03:43.497+0000] {logging_mixin.py:188} INFO - Données de /opt/***/data/processed/2024/constructors.csv chargées avec succès dans la table constructors.
[2025-06-03T19:03:43.501+0000] {base.py:84} INFO - Using connection ID 'f1_postgres_db' for task execution.
[2025-06-03T19:03:43.502+0000] {logging_mixin.py:188} INFO - Exécution : DELETE FROM races WHERE year = 2024;
[2025-06-03T19:03:43.505+0000] {base.py:84} INFO - Using connection ID 'f1_postgres_db' for task execution.
[2025-06-03T19:03:43.507+0000] {sql.py:487} INFO - Running statement: DELETE FROM races WHERE year = 2024;, parameters: None
[2025-06-03T19:03:43.507+0000] {sql.py:496} INFO - Rows affected: 0
[2025-06-03T19:03:43.513+0000] {logging_mixin.py:188} INFO - Erreur lors du chargement de /opt/***/data/processed/2024/races_schedule.csv vers la table races:
[2025-06-03T19:03:43.517+0000] {logging_mixin.py:188} WARNING - Traceback (most recent call last):
[2025-06-03T19:03:43.517+0000] {logging_mixin.py:188} WARNING -   File "/home/***/.local/lib/python3.12/site-packages/sqlalchemy/engine/base.py", line 1890, in _execute_context
    self.dialect.do_executemany(
[2025-06-03T19:03:43.518+0000] {logging_mixin.py:188} WARNING -   File "/home/***/.local/lib/python3.12/site-packages/sqlalchemy/dialects/postgresql/psycopg2.py", line 982, in do_executemany
    context._psycopg2_fetched_rows = xtras.execute_values(
                                     ^^^^^^^^^^^^^^^^^^^^^
[2025-06-03T19:03:43.518+0000] {logging_mixin.py:188} WARNING -   File "/home/***/.local/lib/python3.12/site-packages/psycopg2/extras.py", line 1299, in execute_values
    cur.execute(b''.join(parts))
[2025-06-03T19:03:43.518+0000] {logging_mixin.py:188} WARNING - psycopg2.errors.UndefinedColumn: column "circuit_name" of relation "races" does not exist
LINE 1: ...ces (race_id, year, round, race_name, circuit_id, circuit_na...
                                                             ^
[2025-06-03T19:03:43.518+0000] {logging_mixin.py:188} WARNING - 
The above exception was the direct cause of the following exception:
[2025-06-03T19:03:43.518+0000] {logging_mixin.py:188} WARNING - Traceback (most recent call last):
[2025-06-03T19:03:43.518+0000] {logging_mixin.py:188} WARNING -   File "/opt/***/plugins/etl_scripts/load_to_postgres.py", line 51, in _load_single_csv_to_db
    df.to_sql(name=table_name, con=engine, if_exists='append', index=False, schema='public')
[2025-06-03T19:03:43.518+0000] {logging_mixin.py:188} WARNING -   File "/home/***/.local/lib/python3.12/site-packages/pandas/util/_decorators.py", line 333, in wrapper
    return func(*args, **kwargs)
           ^^^^^^^^^^^^^^^^^^^^^
[2025-06-03T19:03:43.518+0000] {logging_mixin.py:188} WARNING -   File "/home/***/.local/lib/python3.12/site-packages/pandas/core/generic.py", line 3008, in to_sql
    return sql.to_sql(
           ^^^^^^^^^^^
[2025-06-03T19:03:43.519+0000] {logging_mixin.py:188} WARNING -   File "/home/***/.local/lib/python3.12/site-packages/pandas/io/sql.py", line 788, in to_sql
    return pandas_sql.to_sql(
           ^^^^^^^^^^^^^^^^^^
[2025-06-03T19:03:43.519+0000] {logging_mixin.py:188} WARNING -   File "/home/***/.local/lib/python3.12/site-packages/pandas/io/sql.py", line 1958, in to_sql
    total_inserted = sql_engine.insert_records(
                     ^^^^^^^^^^^^^^^^^^^^^^^^^^
[2025-06-03T19:03:43.519+0000] {logging_mixin.py:188} WARNING -   File "/home/***/.local/lib/python3.12/site-packages/pandas/io/sql.py", line 1507, in insert_records
    raise err
[2025-06-03T19:03:43.519+0000] {logging_mixin.py:188} WARNING -   File "/home/***/.local/lib/python3.12/site-packages/pandas/io/sql.py", line 1498, in insert_records
    return table.insert(chunksize=chunksize, method=method)
           ^^^^^^^^^^^^^^^^^^^^^^^^^^^^^^^^^^^^^^^^^^^^^^^^
[2025-06-03T19:03:43.519+0000] {logging_mixin.py:188} WARNING -   File "/home/***/.local/lib/python3.12/site-packages/pandas/io/sql.py", line 1059, in insert
    num_inserted = exec_insert(conn, keys, chunk_iter)
                   ^^^^^^^^^^^^^^^^^^^^^^^^^^^^^^^^^^^
[2025-06-03T19:03:43.519+0000] {logging_mixin.py:188} WARNING -   File "/home/***/.local/lib/python3.12/site-packages/pandas/io/sql.py", line 951, in _execute_insert
    result = conn.execute(self.table.insert(), data)
             ^^^^^^^^^^^^^^^^^^^^^^^^^^^^^^^^^^^^^^^
[2025-06-03T19:03:43.519+0000] {logging_mixin.py:188} WARNING -   File "/home/***/.local/lib/python3.12/site-packages/sqlalchemy/engine/base.py", line 1385, in execute
    return meth(self, multiparams, params, _EMPTY_EXECUTION_OPTS)
           ^^^^^^^^^^^^^^^^^^^^^^^^^^^^^^^^^^^^^^^^^^^^^^^^^^^^^^
[2025-06-03T19:03:43.519+0000] {logging_mixin.py:188} WARNING -   File "/home/***/.local/lib/python3.12/site-packages/sqlalchemy/sql/elements.py", line 334, in _execute_on_connection
    return connection._execute_clauseelement(
           ^^^^^^^^^^^^^^^^^^^^^^^^^^^^^^^^^^
[2025-06-03T19:03:43.519+0000] {logging_mixin.py:188} WARNING -   File "/home/***/.local/lib/python3.12/site-packages/sqlalchemy/engine/base.py", line 1577, in _execute_clauseelement
    ret = self._execute_context(
          ^^^^^^^^^^^^^^^^^^^^^^
[2025-06-03T19:03:43.519+0000] {logging_mixin.py:188} WARNING -   File "/home/***/.local/lib/python3.12/site-packages/sqlalchemy/engine/base.py", line 1953, in _execute_context
    self._handle_dbapi_exception(
[2025-06-03T19:03:43.519+0000] {logging_mixin.py:188} WARNING -   File "/home/***/.local/lib/python3.12/site-packages/sqlalchemy/engine/base.py", line 2134, in _handle_dbapi_exception
    util.raise_(
[2025-06-03T19:03:43.519+0000] {logging_mixin.py:188} WARNING -   File "/home/***/.local/lib/python3.12/site-packages/sqlalchemy/util/compat.py", line 211, in raise_
    raise exception
[2025-06-03T19:03:43.519+0000] {logging_mixin.py:188} WARNING -   File "/home/***/.local/lib/python3.12/site-packages/sqlalchemy/engine/base.py", line 1890, in _execute_context
    self.dialect.do_executemany(
[2025-06-03T19:03:43.519+0000] {logging_mixin.py:188} WARNING -   File "/home/***/.local/lib/python3.12/site-packages/sqlalchemy/dialects/postgresql/psycopg2.py", line 982, in do_executemany
    context._psycopg2_fetched_rows = xtras.execute_values(
                                     ^^^^^^^^^^^^^^^^^^^^^
[2025-06-03T19:03:43.520+0000] {logging_mixin.py:188} WARNING -   File "/home/***/.local/lib/python3.12/site-packages/psycopg2/extras.py", line 1299, in execute_values
    cur.execute(b''.join(parts))
[2025-06-03T19:03:43.520+0000] {logging_mixin.py:188} WARNING - sqlalchemy.exc.ProgrammingError: (psycopg2.errors.UndefinedColumn) column "circuit_name" of relation "races" does not exist
LINE 1: ...ces (race_id, year, round, race_name, circuit_id, circuit_na...
                                                             ^

[SQL: INSERT INTO public.races (race_id, year, round, race_name, circuit_id, circuit_name, circuit_locality, circuit_country, date, time) VALUES (%(race_id)s, %(year)s, %(round)s, %(race_name)s, %(circuit_id)s, %(circuit_name)s, %(circuit_locality)s, %(circuit_country)s, %(date)s, %(time)s)]
[parameters: ({'race_id': '2024_1', 'year': 2024, 'round': 1, 'race_name': 'Bahrain Grand Prix', 'circuit_id': 'bahrain', 'circuit_name': 'Bahrain International Circuit', 'circuit_locality': 'Sakhir', 'circuit_country': 'Bahrain', 'date': '2024-03-02', 'time': '15:00:00Z'}, {'race_id': '2024_2', 'year': 2024, 'round': 2, 'race_name': 'Saudi Arabian Grand Prix', 'circuit_id': 'jeddah', 'circuit_name': 'Jeddah Corniche Circuit', 'circuit_locality': 'Jeddah', 'circuit_country': 'Saudi Arabia', 'date': '2024-03-09', 'time': '17:00:00Z'}, {'race_id': '2024_3', 'year': 2024, 'round': 3, 'race_name': 'Australian Grand Prix', 'circuit_id': 'albert_park', 'circuit_name': 'Albert Park Grand Prix Circuit', 'circuit_locality': 'Melbourne', 'circuit_country': 'Australia', 'date': '2024-03-24', 'time': '04:00:00Z'}, {'race_id': '2024_4', 'year': 2024, 'round': 4, 'race_name': 'Japanese Grand Prix', 'circuit_id': 'suzuka', 'circuit_name': 'Suzuka Circuit', 'circuit_locality': 'Suzuka', 'circuit_country': 'Japan', 'date': '2024-04-07', 'time': '05:00:00Z'}, {'race_id': '2024_5', 'year': 2024, 'round': 5, 'race_name': 'Chinese Grand Prix', 'circuit_id': 'shanghai', 'circuit_name': 'Shanghai International Circuit', 'circuit_locality': 'Shanghai', 'circuit_country': 'China', 'date': '2024-04-21', 'time': '07:00:00Z'}, {'race_id': '2024_6', 'year': 2024, 'round': 6, 'race_name': 'Miami Grand Prix', 'circuit_id': 'miami', 'circuit_name': 'Miami International Autodrome', 'circuit_locality': 'Miami', 'circuit_country': 'USA', 'date': '2024-05-05', 'time': '20:00:00Z'}, {'race_id': '2024_7', 'year': 2024, 'round': 7, 'race_name': 'Emilia Romagna Grand Prix', 'circuit_id': 'imola', 'circuit_name': 'Autodromo Enzo e Dino Ferrari', 'circuit_locality': 'Imola', 'circuit_country': 'Italy', 'date': '2024-05-19', 'time': '13:00:00Z'}, {'race_id': '2024_8', 'year': 2024, 'round': 8, 'race_name': 'Monaco Grand Prix', 'circuit_id': 'monaco', 'circuit_name': 'Circuit de Monaco', 'circuit_locality': 'Monte-Carlo', 'circuit_country': 'Monaco', 'date': '2024-05-26', 'time': '13:00:00Z'}  ... displaying 10 of 24 total bound parameter sets ...  {'race_id': '2024_23', 'year': 2024, 'round': 23, 'race_name': 'Qatar Grand Prix', 'circuit_id': 'losail', 'circuit_name': 'Losail International Circuit', 'circuit_locality': 'Al Daayen', 'circuit_country': 'Qatar', 'date': '2024-12-01', 'time': '17:00:00Z'}, {'race_id': '2024_24', 'year': 2024, 'round': 24, 'race_name': 'Abu Dhabi Grand Prix', 'circuit_id': 'yas_marina', 'circuit_name': 'Yas Marina Circuit', 'circuit_locality': 'Abu Dhabi', 'circuit_country': 'UAE', 'date': '2024-12-08', 'time': '13:00:00Z'})]
(Background on this error at: https://sqlalche.me/e/14/f405)
[2025-06-03T19:03:43.520+0000] {logging_mixin.py:188} INFO - Échec du chargement pour races. Poursuite avec les autres tables si possible.
[2025-06-03T19:03:43.525+0000] {base.py:84} INFO - Using connection ID 'f1_postgres_db' for task execution.
[2025-06-03T19:03:43.525+0000] {logging_mixin.py:188} INFO - Exécution : DELETE FROM results WHERE race_id LIKE '2024_%';
[2025-06-03T19:03:43.530+0000] {base.py:84} INFO - Using connection ID 'f1_postgres_db' for task execution.
[2025-06-03T19:03:43.533+0000] {sql.py:487} INFO - Running statement: DELETE FROM results WHERE race_id LIKE '2024_%';, parameters: None
[2025-06-03T19:03:43.534+0000] {sql.py:496} INFO - Rows affected: 0
[2025-06-03T19:03:43.557+0000] {logging_mixin.py:188} INFO - Erreur lors du chargement de /opt/***/data/processed/2024/detailed_results.csv vers la table results:
[2025-06-03T19:03:43.559+0000] {logging_mixin.py:188} WARNING - Traceback (most recent call last):
[2025-06-03T19:03:43.559+0000] {logging_mixin.py:188} WARNING -   File "/home/***/.local/lib/python3.12/site-packages/sqlalchemy/engine/base.py", line 1890, in _execute_context
    self.dialect.do_executemany(
[2025-06-03T19:03:43.559+0000] {logging_mixin.py:188} WARNING -   File "/home/***/.local/lib/python3.12/site-packages/sqlalchemy/dialects/postgresql/psycopg2.py", line 982, in do_executemany
    context._psycopg2_fetched_rows = xtras.execute_values(
                                     ^^^^^^^^^^^^^^^^^^^^^
[2025-06-03T19:03:43.559+0000] {logging_mixin.py:188} WARNING -   File "/home/***/.local/lib/python3.12/site-packages/psycopg2/extras.py", line 1299, in execute_values
    cur.execute(b''.join(parts))
[2025-06-03T19:03:43.559+0000] {logging_mixin.py:188} WARNING - psycopg2.errors.UniqueViolation: duplicate key value violates unique constraint "unique_result_per_driver_per_race"
DETAIL:  Key (race_id, driver_id)=(2024_1, max_verstappen) already exists.
[2025-06-03T19:03:43.559+0000] {logging_mixin.py:188} WARNING - 
The above exception was the direct cause of the following exception:
[2025-06-03T19:03:43.559+0000] {logging_mixin.py:188} WARNING - Traceback (most recent call last):
[2025-06-03T19:03:43.560+0000] {logging_mixin.py:188} WARNING -   File "/opt/***/plugins/etl_scripts/load_to_postgres.py", line 51, in _load_single_csv_to_db
    df.to_sql(name=table_name, con=engine, if_exists='append', index=False, schema='public')
[2025-06-03T19:03:43.560+0000] {logging_mixin.py:188} WARNING -   File "/home/***/.local/lib/python3.12/site-packages/pandas/util/_decorators.py", line 333, in wrapper
    return func(*args, **kwargs)
           ^^^^^^^^^^^^^^^^^^^^^
[2025-06-03T19:03:43.560+0000] {logging_mixin.py:188} WARNING -   File "/home/***/.local/lib/python3.12/site-packages/pandas/core/generic.py", line 3008, in to_sql
    return sql.to_sql(
           ^^^^^^^^^^^
[2025-06-03T19:03:43.560+0000] {logging_mixin.py:188} WARNING -   File "/home/***/.local/lib/python3.12/site-packages/pandas/io/sql.py", line 788, in to_sql
    return pandas_sql.to_sql(
           ^^^^^^^^^^^^^^^^^^
[2025-06-03T19:03:43.560+0000] {logging_mixin.py:188} WARNING -   File "/home/***/.local/lib/python3.12/site-packages/pandas/io/sql.py", line 1958, in to_sql
    total_inserted = sql_engine.insert_records(
                     ^^^^^^^^^^^^^^^^^^^^^^^^^^
[2025-06-03T19:03:43.560+0000] {logging_mixin.py:188} WARNING -   File "/home/***/.local/lib/python3.12/site-packages/pandas/io/sql.py", line 1507, in insert_records
    raise err
[2025-06-03T19:03:43.560+0000] {logging_mixin.py:188} WARNING -   File "/home/***/.local/lib/python3.12/site-packages/pandas/io/sql.py", line 1498, in insert_records
    return table.insert(chunksize=chunksize, method=method)
           ^^^^^^^^^^^^^^^^^^^^^^^^^^^^^^^^^^^^^^^^^^^^^^^^
[2025-06-03T19:03:43.560+0000] {logging_mixin.py:188} WARNING -   File "/home/***/.local/lib/python3.12/site-packages/pandas/io/sql.py", line 1059, in insert
    num_inserted = exec_insert(conn, keys, chunk_iter)
                   ^^^^^^^^^^^^^^^^^^^^^^^^^^^^^^^^^^^
[2025-06-03T19:03:43.560+0000] {logging_mixin.py:188} WARNING -   File "/home/***/.local/lib/python3.12/site-packages/pandas/io/sql.py", line 951, in _execute_insert
    result = conn.execute(self.table.insert(), data)
             ^^^^^^^^^^^^^^^^^^^^^^^^^^^^^^^^^^^^^^^
[2025-06-03T19:03:43.560+0000] {logging_mixin.py:188} WARNING -   File "/home/***/.local/lib/python3.12/site-packages/sqlalchemy/engine/base.py", line 1385, in execute
    return meth(self, multiparams, params, _EMPTY_EXECUTION_OPTS)
           ^^^^^^^^^^^^^^^^^^^^^^^^^^^^^^^^^^^^^^^^^^^^^^^^^^^^^^
[2025-06-03T19:03:43.560+0000] {logging_mixin.py:188} WARNING -   File "/home/***/.local/lib/python3.12/site-packages/sqlalchemy/sql/elements.py", line 334, in _execute_on_connection
    return connection._execute_clauseelement(
           ^^^^^^^^^^^^^^^^^^^^^^^^^^^^^^^^^^
[2025-06-03T19:03:43.560+0000] {logging_mixin.py:188} WARNING -   File "/home/***/.local/lib/python3.12/site-packages/sqlalchemy/engine/base.py", line 1577, in _execute_clauseelement
    ret = self._execute_context(
          ^^^^^^^^^^^^^^^^^^^^^^
[2025-06-03T19:03:43.560+0000] {logging_mixin.py:188} WARNING -   File "/home/***/.local/lib/python3.12/site-packages/sqlalchemy/engine/base.py", line 1953, in _execute_context
    self._handle_dbapi_exception(
[2025-06-03T19:03:43.561+0000] {logging_mixin.py:188} WARNING -   File "/home/***/.local/lib/python3.12/site-packages/sqlalchemy/engine/base.py", line 2134, in _handle_dbapi_exception
    util.raise_(
[2025-06-03T19:03:43.561+0000] {logging_mixin.py:188} WARNING -   File "/home/***/.local/lib/python3.12/site-packages/sqlalchemy/util/compat.py", line 211, in raise_
    raise exception
[2025-06-03T19:03:43.561+0000] {logging_mixin.py:188} WARNING -   File "/home/***/.local/lib/python3.12/site-packages/sqlalchemy/engine/base.py", line 1890, in _execute_context
    self.dialect.do_executemany(
[2025-06-03T19:03:43.561+0000] {logging_mixin.py:188} WARNING -   File "/home/***/.local/lib/python3.12/site-packages/sqlalchemy/dialects/postgresql/psycopg2.py", line 982, in do_executemany
    context._psycopg2_fetched_rows = xtras.execute_values(
                                     ^^^^^^^^^^^^^^^^^^^^^
[2025-06-03T19:03:43.561+0000] {logging_mixin.py:188} WARNING -   File "/home/***/.local/lib/python3.12/site-packages/psycopg2/extras.py", line 1299, in execute_values
    cur.execute(b''.join(parts))
[2025-06-03T19:03:43.561+0000] {logging_mixin.py:188} WARNING - sqlalchemy.exc.IntegrityError: (psycopg2.errors.UniqueViolation) duplicate key value violates unique constraint "unique_result_per_driver_per_race"
DETAIL:  Key (race_id, driver_id)=(2024_1, max_verstappen) already exists.

[SQL: INSERT INTO public.results (race_id, driver_id, constructor_id, car_number, grid_position, final_position, position_text, points, laps_completed, status, time_millis, time_text) VALUES (%(race_id)s, %(driver_id)s, %(constructor_id)s, %(car_number)s, %(grid_position)s, %(final_position)s, %(position_text)s, %(points)s, %(laps_completed)s, %(status)s, %(time_millis)s, %(time_text)s)]
[parameters: ({'race_id': '2024_1', 'driver_id': 'max_verstappen', 'constructor_id': 'red_bull', 'car_number': 1, 'grid_position': 1, 'final_position': 1, 'position_text': '1', 'points': 26.0, 'laps_completed': 57, 'status': 'Finished', 'time_millis': 5504742.0, 'time_text': '1:31:44.742'}, {'race_id': '2024_1', 'driver_id': 'perez', 'constructor_id': 'red_bull', 'car_number': 11, 'grid_position': 5, 'final_position': 2, 'position_text': '2', 'points': 18.0, 'laps_completed': 57, 'status': 'Finished', 'time_millis': 5527199.0, 'time_text': '+22.457'}, {'race_id': '2024_1', 'driver_id': 'sainz', 'constructor_id': 'ferrari', 'car_number': 55, 'grid_position': 4, 'final_position': 3, 'position_text': '3', 'points': 15.0, 'laps_completed': 57, 'status': 'Finished', 'time_millis': 5529852.0, 'time_text': '+25.110'}, {'race_id': '2024_1', 'driver_id': 'leclerc', 'constructor_id': 'ferrari', 'car_number': 16, 'grid_position': 2, 'final_position': 4, 'position_text': '4', 'points': 12.0, 'laps_completed': 57, 'status': 'Finished', 'time_millis': 5544411.0, 'time_text': '+39.669'}, {'race_id': '2024_1', 'driver_id': 'russell', 'constructor_id': 'mercedes', 'car_number': 63, 'grid_position': 3, 'final_position': 5, 'position_text': '5', 'points': 10.0, 'laps_completed': 57, 'status': 'Finished', 'time_millis': 5551530.0, 'time_text': '+46.788'}, {'race_id': '2024_1', 'driver_id': 'norris', 'constructor_id': 'mclaren', 'car_number': 4, 'grid_position': 7, 'final_position': 6, 'position_text': '6', 'points': 8.0, 'laps_completed': 57, 'status': 'Finished', 'time_millis': 5553200.0, 'time_text': '+48.458'}, {'race_id': '2024_1', 'driver_id': 'hamilton', 'constructor_id': 'mercedes', 'car_number': 44, 'grid_position': 9, 'final_position': 7, 'position_text': '7', 'points': 6.0, 'laps_completed': 57, 'status': 'Finished', 'time_millis': 5555066.0, 'time_text': '+50.324'}, {'race_id': '2024_1', 'driver_id': 'piastri', 'constructor_id': 'mclaren', 'car_number': 81, 'grid_position': 8, 'final_position': 8, 'position_text': '8', 'points': 4.0, 'laps_completed': 57, 'status': 'Finished', 'time_millis': 5560824.0, 'time_text': '+56.082'}  ... displaying 10 of 737 total bound parameter sets ...  {'race_id': '2024_4', 'driver_id': 'ricciardo', 'constructor_id': 'rb', 'car_number': 3, 'grid_position': 11, 'final_position': 19, 'position_text': 'R', 'points': 0.0, 'laps_completed': 0, 'status': 'Accident', 'time_millis': None, 'time_text': None}, {'race_id': '2024_4', 'driver_id': 'albon', 'constructor_id': 'williams', 'car_number': 23, 'grid_position': 14, 'final_position': 20, 'position_text': 'R', 'points': 0.0, 'laps_completed': 0, 'status': 'Accident', 'time_millis': None, 'time_text': None})]
(Background on this error at: https://sqlalche.me/e/14/gkpj)
[2025-06-03T19:03:43.561+0000] {logging_mixin.py:188} INFO - Échec du chargement pour results. Poursuite avec les autres tables si possible.
[2025-06-03T19:03:43.561+0000] {taskinstance.py:441} INFO - ::group::Post task execution logs
[2025-06-03T19:03:43.561+0000] {taskinstance.py:2905} ERROR - Task failed with exception
Traceback (most recent call last):
  File "/home/airflow/.local/lib/python3.12/site-packages/airflow/models/taskinstance.py", line 465, in _execute_task
    result = _execute_callable(context=context, **execute_callable_kwargs)
             ^^^^^^^^^^^^^^^^^^^^^^^^^^^^^^^^^^^^^^^^^^^^^^^^^^^^^^^^^^^^^
  File "/home/airflow/.local/lib/python3.12/site-packages/airflow/models/taskinstance.py", line 432, in _execute_callable
    return execute_callable(context=context, **execute_callable_kwargs)
           ^^^^^^^^^^^^^^^^^^^^^^^^^^^^^^^^^^^^^^^^^^^^^^^^^^^^^^^^^^^^
  File "/home/airflow/.local/lib/python3.12/site-packages/airflow/models/baseoperator.py", line 401, in wrapper
    return func(self, *args, **kwargs)
           ^^^^^^^^^^^^^^^^^^^^^^^^^^^
  File "/home/airflow/.local/lib/python3.12/site-packages/airflow/operators/python.py", line 235, in execute
    return_value = self.execute_callable()
                   ^^^^^^^^^^^^^^^^^^^^^^^
  File "/home/airflow/.local/lib/python3.12/site-packages/airflow/operators/python.py", line 252, in execute_callable
    return self.python_callable(*self.op_args, **self.op_kwargs)
           ^^^^^^^^^^^^^^^^^^^^^^^^^^^^^^^^^^^^^^^^^^^^^^^^^^^^^
  File "/opt/airflow/plugins/etl_scripts/load_to_postgres.py", line 92, in load_all_processed_data_to_postgres
    raise ValueError(f"Un ou plusieurs chargements en base de données ont échoué pour l'année {year}.")
ValueError: Un ou plusieurs chargements en base de données ont échoué pour l'année 2024.
[2025-06-03T19:03:43.567+0000] {taskinstance.py:1206} INFO - Marking task as FAILED. dag_id=f1_data_extraction_pipeline, task_id=load_data_to_postgres, run_id=manual__2025-06-03T19:03:35+00:00, execution_date=20250603T190335, start_date=20250603T190343, end_date=20250603T190343
[2025-06-03T19:03:43.571+0000] {standard_task_runner.py:110} ERROR - Failed to execute job 11 for task load_data_to_postgres (Un ou plusieurs chargements en base de données ont échoué pour l'année 2024.; 268)
[2025-06-03T19:03:43.588+0000] {local_task_job_runner.py:240} INFO - Task exited with return code 1
[2025-06-03T19:03:43.597+0000] {taskinstance.py:3503} INFO - 0 downstream tasks scheduled from follow-on schedule check
[2025-06-03T19:03:43.598+0000] {local_task_job_runner.py:222} INFO - ::endgroup::
