[2025-06-04T09:24:59.854+0000] {local_task_job_runner.py:120} INFO - ::group::Pre task execution logs
[2025-06-04T09:24:59.868+0000] {taskinstance.py:2076} INFO - Dependencies all met for dep_context=non-requeueable deps ti=<TaskInstance: f1_data_extraction_pipeline.load_data_to_postgres manual__2025-06-04T09:24:23+00:00 [queued]>
[2025-06-04T09:24:59.872+0000] {taskinstance.py:2076} INFO - Dependencies all met for dep_context=requeueable deps ti=<TaskInstance: f1_data_extraction_pipeline.load_data_to_postgres manual__2025-06-04T09:24:23+00:00 [queued]>
[2025-06-04T09:24:59.872+0000] {taskinstance.py:2306} INFO - Starting attempt 1 of 1
[2025-06-04T09:24:59.876+0000] {taskinstance.py:2330} INFO - Executing <Task(PythonOperator): load_data_to_postgres> on 2025-06-04 09:24:23+00:00
[2025-06-04T09:24:59.881+0000] {logging_mixin.py:188} WARNING - /home/***/.local/lib/python3.12/site-packages/***/task/task_runner/standard_task_runner.py:61 DeprecationWarning: This process (pid=357) is multi-threaded, use of fork() may lead to deadlocks in the child.
[2025-06-04T09:24:59.882+0000] {standard_task_runner.py:63} INFO - Started process 358 to run task
[2025-06-04T09:24:59.881+0000] {standard_task_runner.py:90} INFO - Running: ['***', 'tasks', 'run', 'f1_data_extraction_pipeline', 'load_data_to_postgres', 'manual__2025-06-04T09:24:23+00:00', '--job-id', '11', '--raw', '--subdir', 'DAGS_FOLDER/f1_pipeline.py', '--cfg-path', '/tmp/tmphaclnf78']
[2025-06-04T09:24:59.882+0000] {standard_task_runner.py:91} INFO - Job 11: Subtask load_data_to_postgres
[2025-06-04T09:24:59.904+0000] {task_command.py:426} INFO - Running <TaskInstance: f1_data_extraction_pipeline.load_data_to_postgres manual__2025-06-04T09:24:23+00:00 [running]> on host bbce21915965
[2025-06-04T09:25:00.021+0000] {taskinstance.py:2648} INFO - Exporting env vars: AIRFLOW_CTX_DAG_OWNER='***' AIRFLOW_CTX_DAG_ID='f1_data_extraction_pipeline' AIRFLOW_CTX_TASK_ID='load_data_to_postgres' AIRFLOW_CTX_EXECUTION_DATE='2025-06-04T09:24:23+00:00' AIRFLOW_CTX_TRY_NUMBER='1' AIRFLOW_CTX_DAG_RUN_ID='manual__2025-06-04T09:24:23+00:00'
[2025-06-04T09:25:00.021+0000] {taskinstance.py:430} INFO - ::endgroup::
[2025-06-04T09:25:00.033+0000] {logging_mixin.py:188} INFO - ✔️  Upsert terminé pour circuits_info.csv → circuits
[2025-06-04T09:25:00.034+0000] {logging_mixin.py:188} INFO - ✔️  Chargé par COPY: races_schedule.csv → races
[2025-06-04T09:25:00.035+0000] {taskinstance.py:441} INFO - ::group::Post task execution logs
[2025-06-04T09:25:00.035+0000] {taskinstance.py:2905} ERROR - Task failed with exception
Traceback (most recent call last):
  File "/home/airflow/.local/lib/python3.12/site-packages/airflow/models/taskinstance.py", line 465, in _execute_task
    result = _execute_callable(context=context, **execute_callable_kwargs)
             ^^^^^^^^^^^^^^^^^^^^^^^^^^^^^^^^^^^^^^^^^^^^^^^^^^^^^^^^^^^^^
  File "/home/airflow/.local/lib/python3.12/site-packages/airflow/models/taskinstance.py", line 432, in _execute_callable
    return execute_callable(context=context, **execute_callable_kwargs)
           ^^^^^^^^^^^^^^^^^^^^^^^^^^^^^^^^^^^^^^^^^^^^^^^^^^^^^^^^^^^^
  File "/home/airflow/.local/lib/python3.12/site-packages/airflow/models/baseoperator.py", line 401, in wrapper
    return func(self, *args, **kwargs)
           ^^^^^^^^^^^^^^^^^^^^^^^^^^^
  File "/home/airflow/.local/lib/python3.12/site-packages/airflow/operators/python.py", line 235, in execute
    return_value = self.execute_callable()
                   ^^^^^^^^^^^^^^^^^^^^^^^
  File "/home/airflow/.local/lib/python3.12/site-packages/airflow/operators/python.py", line 252, in execute_callable
    return self.python_callable(*self.op_args, **self.op_kwargs)
           ^^^^^^^^^^^^^^^^^^^^^^^^^^^^^^^^^^^^^^^^^^^^^^^^^^^^^
  File "/opt/airflow/dags/f1_pipeline.py", line 53, in _load_to_postgres_callable
    load_year_into_postgres(int(year))
  File "/opt/airflow/plugins/etl_scripts/load_to_postgres.py", line 100, in load_year_into_postgres
    copy_table(cursor, paths["drivers"],
  File "/opt/airflow/plugins/etl_scripts/load_to_postgres.py", line 80, in copy_table
    cursor.copy_expert(sql=copy_sql, file=f)
psycopg2.errors.UniqueViolation: duplicate key value violates unique constraint "drivers_pkey"
DETAIL:  Key (driver_id)=(max_verstappen) already exists.
CONTEXT:  COPY drivers, line 2

[2025-06-04T09:25:00.040+0000] {taskinstance.py:1206} INFO - Marking task as FAILED. dag_id=f1_data_extraction_pipeline, task_id=load_data_to_postgres, run_id=manual__2025-06-04T09:24:23+00:00, execution_date=20250604T092423, start_date=20250604T092459, end_date=20250604T092500
[2025-06-04T09:25:00.044+0000] {standard_task_runner.py:110} ERROR - Failed to execute job 11 for task load_data_to_postgres (duplicate key value violates unique constraint "drivers_pkey"
DETAIL:  Key (driver_id)=(max_verstappen) already exists.
CONTEXT:  COPY drivers, line 2
; 358)
[2025-06-04T09:25:00.065+0000] {local_task_job_runner.py:240} INFO - Task exited with return code 1
[2025-06-04T09:25:00.074+0000] {taskinstance.py:3503} INFO - 0 downstream tasks scheduled from follow-on schedule check
[2025-06-04T09:25:00.075+0000] {local_task_job_runner.py:222} INFO - ::endgroup::
