[2025-06-04T08:45:52.976+0000] {local_task_job_runner.py:120} INFO - ::group::Pre task execution logs
[2025-06-04T08:45:52.992+0000] {taskinstance.py:2076} INFO - Dependencies all met for dep_context=non-requeueable deps ti=<TaskInstance: f1_data_extraction_pipeline.load_data_to_postgres manual__2025-06-04T08:45:40+00:00 [queued]>
[2025-06-04T08:45:52.996+0000] {taskinstance.py:2076} INFO - Dependencies all met for dep_context=requeueable deps ti=<TaskInstance: f1_data_extraction_pipeline.load_data_to_postgres manual__2025-06-04T08:45:40+00:00 [queued]>
[2025-06-04T08:45:52.996+0000] {taskinstance.py:2306} INFO - Starting attempt 1 of 1
[2025-06-04T08:45:53.003+0000] {taskinstance.py:2330} INFO - Executing <Task(PythonOperator): load_data_to_postgres> on 2025-06-04 08:45:40+00:00
[2025-06-04T08:45:53.006+0000] {standard_task_runner.py:90} INFO - Running: ['***', 'tasks', 'run', 'f1_data_extraction_pipeline', 'load_data_to_postgres', 'manual__2025-06-04T08:45:40+00:00', '--job-id', '21', '--raw', '--subdir', 'DAGS_FOLDER/f1_pipeline.py', '--cfg-path', '/tmp/tmprg887wtg']
[2025-06-04T08:45:53.010+0000] {standard_task_runner.py:91} INFO - Job 21: Subtask load_data_to_postgres
[2025-06-04T08:45:53.109+0000] {logging_mixin.py:188} WARNING - /home/***/.local/lib/python3.12/site-packages/***/task/task_runner/standard_task_runner.py:61 DeprecationWarning: This process (pid=394) is multi-threaded, use of fork() may lead to deadlocks in the child.
[2025-06-04T08:45:53.109+0000] {standard_task_runner.py:63} INFO - Started process 395 to run task
[2025-06-04T08:45:53.135+0000] {task_command.py:426} INFO - Running <TaskInstance: f1_data_extraction_pipeline.load_data_to_postgres manual__2025-06-04T08:45:40+00:00 [running]> on host 2d9db0dcbf62
[2025-06-04T08:45:53.174+0000] {taskinstance.py:2648} INFO - Exporting env vars: AIRFLOW_CTX_DAG_OWNER='***' AIRFLOW_CTX_DAG_ID='f1_data_extraction_pipeline' AIRFLOW_CTX_TASK_ID='load_data_to_postgres' AIRFLOW_CTX_EXECUTION_DATE='2025-06-04T08:45:40+00:00' AIRFLOW_CTX_TRY_NUMBER='1' AIRFLOW_CTX_DAG_RUN_ID='manual__2025-06-04T08:45:40+00:00'
[2025-06-04T08:45:53.174+0000] {taskinstance.py:430} INFO - ::endgroup::
[2025-06-04T08:45:53.179+0000] {logging_mixin.py:188} INFO - Début du chargement en base de données pour l'année 2024.
[2025-06-04T08:45:53.179+0000] {logging_mixin.py:188} INFO - Nettoyage préalable : DELETE FROM results WHERE race_id LIKE '2024_%';
[2025-06-04T08:45:53.189+0000] {base.py:84} INFO - Using connection ID 'f1_postgres_db' for task execution.
[2025-06-04T08:45:53.192+0000] {sql.py:487} INFO - Running statement: DELETE FROM results WHERE race_id LIKE '2024_%';, parameters: None
[2025-06-04T08:45:53.193+0000] {sql.py:496} INFO - Rows affected: 179
[2025-06-04T08:45:53.194+0000] {logging_mixin.py:188} INFO - Nettoyage préalable : DELETE FROM races WHERE year = 2024;
[2025-06-04T08:45:53.197+0000] {base.py:84} INFO - Using connection ID 'f1_postgres_db' for task execution.
[2025-06-04T08:45:53.200+0000] {sql.py:487} INFO - Running statement: DELETE FROM races WHERE year = 2024;, parameters: None
[2025-06-04T08:45:53.201+0000] {sql.py:496} INFO - Rows affected: 24
[2025-06-04T08:45:53.201+0000] {logging_mixin.py:188} INFO - 
--- Début du traitement pour circuits_info.csv vers table circuits ---
[2025-06-04T08:45:53.207+0000] {base.py:84} INFO - Using connection ID 'f1_postgres_db' for task execution.
[2025-06-04T08:45:53.217+0000] {logging_mixin.py:188} INFO - Erreur générique non attrapée spécifiquement lors du chargement de /opt/***/data/processed/2024/circuits_info.csv vers la table circuits:
[2025-06-04T08:45:53.223+0000] {logging_mixin.py:188} WARNING - Traceback (most recent call last):
[2025-06-04T08:45:53.223+0000] {logging_mixin.py:188} WARNING -   File "/home/***/.local/lib/python3.12/site-packages/sqlalchemy/engine/base.py", line 1890, in _execute_context
    self.dialect.do_executemany(
[2025-06-04T08:45:53.223+0000] {logging_mixin.py:188} WARNING -   File "/home/***/.local/lib/python3.12/site-packages/sqlalchemy/dialects/postgresql/psycopg2.py", line 982, in do_executemany
    context._psycopg2_fetched_rows = xtras.execute_values(
                                     ^^^^^^^^^^^^^^^^^^^^^
[2025-06-04T08:45:53.223+0000] {logging_mixin.py:188} WARNING -   File "/home/***/.local/lib/python3.12/site-packages/psycopg2/extras.py", line 1299, in execute_values
    cur.execute(b''.join(parts))
[2025-06-04T08:45:53.223+0000] {logging_mixin.py:188} WARNING - psycopg2.errors.UniqueViolation: duplicate key value violates unique constraint "circuits_pkey"
DETAIL:  Key (circuit_id)=(bahrain) already exists.
[2025-06-04T08:45:53.224+0000] {logging_mixin.py:188} WARNING - 
The above exception was the direct cause of the following exception:
[2025-06-04T08:45:53.224+0000] {logging_mixin.py:188} WARNING - Traceback (most recent call last):
[2025-06-04T08:45:53.224+0000] {logging_mixin.py:188} WARNING -   File "/opt/***/plugins/etl_scripts/load_to_postgres.py", line 42, in _load_single_csv_to_db
    df.to_sql(name=table_name, con=engine, if_exists='append', index=False, schema='public')
[2025-06-04T08:45:53.224+0000] {logging_mixin.py:188} WARNING -   File "/home/***/.local/lib/python3.12/site-packages/pandas/util/_decorators.py", line 333, in wrapper
    return func(*args, **kwargs)
           ^^^^^^^^^^^^^^^^^^^^^
[2025-06-04T08:45:53.224+0000] {logging_mixin.py:188} WARNING -   File "/home/***/.local/lib/python3.12/site-packages/pandas/core/generic.py", line 3008, in to_sql
    return sql.to_sql(
           ^^^^^^^^^^^
[2025-06-04T08:45:53.224+0000] {logging_mixin.py:188} WARNING -   File "/home/***/.local/lib/python3.12/site-packages/pandas/io/sql.py", line 788, in to_sql
    return pandas_sql.to_sql(
           ^^^^^^^^^^^^^^^^^^
[2025-06-04T08:45:53.224+0000] {logging_mixin.py:188} WARNING -   File "/home/***/.local/lib/python3.12/site-packages/pandas/io/sql.py", line 1958, in to_sql
    total_inserted = sql_engine.insert_records(
                     ^^^^^^^^^^^^^^^^^^^^^^^^^^
[2025-06-04T08:45:53.224+0000] {logging_mixin.py:188} WARNING -   File "/home/***/.local/lib/python3.12/site-packages/pandas/io/sql.py", line 1507, in insert_records
    raise err
[2025-06-04T08:45:53.224+0000] {logging_mixin.py:188} WARNING -   File "/home/***/.local/lib/python3.12/site-packages/pandas/io/sql.py", line 1498, in insert_records
    return table.insert(chunksize=chunksize, method=method)
           ^^^^^^^^^^^^^^^^^^^^^^^^^^^^^^^^^^^^^^^^^^^^^^^^
[2025-06-04T08:45:53.224+0000] {logging_mixin.py:188} WARNING -   File "/home/***/.local/lib/python3.12/site-packages/pandas/io/sql.py", line 1059, in insert
    num_inserted = exec_insert(conn, keys, chunk_iter)
                   ^^^^^^^^^^^^^^^^^^^^^^^^^^^^^^^^^^^
[2025-06-04T08:45:53.225+0000] {logging_mixin.py:188} WARNING -   File "/home/***/.local/lib/python3.12/site-packages/pandas/io/sql.py", line 951, in _execute_insert
    result = conn.execute(self.table.insert(), data)
             ^^^^^^^^^^^^^^^^^^^^^^^^^^^^^^^^^^^^^^^
[2025-06-04T08:45:53.225+0000] {logging_mixin.py:188} WARNING -   File "/home/***/.local/lib/python3.12/site-packages/sqlalchemy/engine/base.py", line 1385, in execute
    return meth(self, multiparams, params, _EMPTY_EXECUTION_OPTS)
           ^^^^^^^^^^^^^^^^^^^^^^^^^^^^^^^^^^^^^^^^^^^^^^^^^^^^^^
[2025-06-04T08:45:53.225+0000] {logging_mixin.py:188} WARNING -   File "/home/***/.local/lib/python3.12/site-packages/sqlalchemy/sql/elements.py", line 334, in _execute_on_connection
    return connection._execute_clauseelement(
           ^^^^^^^^^^^^^^^^^^^^^^^^^^^^^^^^^^
[2025-06-04T08:45:53.225+0000] {logging_mixin.py:188} WARNING -   File "/home/***/.local/lib/python3.12/site-packages/sqlalchemy/engine/base.py", line 1577, in _execute_clauseelement
    ret = self._execute_context(
          ^^^^^^^^^^^^^^^^^^^^^^
[2025-06-04T08:45:53.225+0000] {logging_mixin.py:188} WARNING -   File "/home/***/.local/lib/python3.12/site-packages/sqlalchemy/engine/base.py", line 1953, in _execute_context
    self._handle_dbapi_exception(
[2025-06-04T08:45:53.225+0000] {logging_mixin.py:188} WARNING -   File "/home/***/.local/lib/python3.12/site-packages/sqlalchemy/engine/base.py", line 2134, in _handle_dbapi_exception
    util.raise_(
[2025-06-04T08:45:53.225+0000] {logging_mixin.py:188} WARNING -   File "/home/***/.local/lib/python3.12/site-packages/sqlalchemy/util/compat.py", line 211, in raise_
    raise exception
[2025-06-04T08:45:53.225+0000] {logging_mixin.py:188} WARNING -   File "/home/***/.local/lib/python3.12/site-packages/sqlalchemy/engine/base.py", line 1890, in _execute_context
    self.dialect.do_executemany(
[2025-06-04T08:45:53.225+0000] {logging_mixin.py:188} WARNING -   File "/home/***/.local/lib/python3.12/site-packages/sqlalchemy/dialects/postgresql/psycopg2.py", line 982, in do_executemany
    context._psycopg2_fetched_rows = xtras.execute_values(
                                     ^^^^^^^^^^^^^^^^^^^^^
[2025-06-04T08:45:53.225+0000] {logging_mixin.py:188} WARNING -   File "/home/***/.local/lib/python3.12/site-packages/psycopg2/extras.py", line 1299, in execute_values
    cur.execute(b''.join(parts))
[2025-06-04T08:45:53.225+0000] {logging_mixin.py:188} WARNING - sqlalchemy.exc.IntegrityError: (psycopg2.errors.UniqueViolation) duplicate key value violates unique constraint "circuits_pkey"
DETAIL:  Key (circuit_id)=(bahrain) already exists.

[SQL: INSERT INTO public.circuits (circuit_id, circuit_name, locality, country) VALUES (%(circuit_id)s, %(circuit_name)s, %(locality)s, %(country)s)]
[parameters: ({'circuit_id': 'bahrain', 'circuit_name': 'Bahrain International Circuit', 'locality': 'Sakhir', 'country': 'Bahrain'}, {'circuit_id': 'jeddah', 'circuit_name': 'Jeddah Corniche Circuit', 'locality': 'Jeddah', 'country': 'Saudi Arabia'}, {'circuit_id': 'albert_park', 'circuit_name': 'Albert Park Grand Prix Circuit', 'locality': 'Melbourne', 'country': 'Australia'}, {'circuit_id': 'suzuka', 'circuit_name': 'Suzuka Circuit', 'locality': 'Suzuka', 'country': 'Japan'}, {'circuit_id': 'shanghai', 'circuit_name': 'Shanghai International Circuit', 'locality': 'Shanghai', 'country': 'China'}, {'circuit_id': 'miami', 'circuit_name': 'Miami International Autodrome', 'locality': 'Miami', 'country': 'USA'}, {'circuit_id': 'imola', 'circuit_name': 'Autodromo Enzo e Dino Ferrari', 'locality': 'Imola', 'country': 'Italy'}, {'circuit_id': 'monaco', 'circuit_name': 'Circuit de Monaco', 'locality': 'Monte-Carlo', 'country': 'Monaco'}  ... displaying 10 of 24 total bound parameter sets ...  {'circuit_id': 'losail', 'circuit_name': 'Losail International Circuit', 'locality': 'Al Daayen', 'country': 'Qatar'}, {'circuit_id': 'yas_marina', 'circuit_name': 'Yas Marina Circuit', 'locality': 'Abu Dhabi', 'country': 'UAE'})]
(Background on this error at: https://sqlalche.me/e/14/gkpj)
[2025-06-04T08:45:53.225+0000] {logging_mixin.py:188} INFO - --- Résultat pour circuits_info.csv: ÉCHEC ---
[2025-06-04T08:45:53.225+0000] {logging_mixin.py:188} INFO - 
--- Début du traitement pour drivers.csv vers table drivers ---
[2025-06-04T08:45:53.231+0000] {base.py:84} INFO - Using connection ID 'f1_postgres_db' for task execution.
[2025-06-04T08:45:53.238+0000] {logging_mixin.py:188} INFO - Erreur générique non attrapée spécifiquement lors du chargement de /opt/***/data/processed/2024/drivers.csv vers la table drivers:
[2025-06-04T08:45:53.239+0000] {logging_mixin.py:188} WARNING - Traceback (most recent call last):
[2025-06-04T08:45:53.239+0000] {logging_mixin.py:188} WARNING -   File "/home/***/.local/lib/python3.12/site-packages/sqlalchemy/engine/base.py", line 1890, in _execute_context
    self.dialect.do_executemany(
[2025-06-04T08:45:53.239+0000] {logging_mixin.py:188} WARNING -   File "/home/***/.local/lib/python3.12/site-packages/sqlalchemy/dialects/postgresql/psycopg2.py", line 982, in do_executemany
    context._psycopg2_fetched_rows = xtras.execute_values(
                                     ^^^^^^^^^^^^^^^^^^^^^
[2025-06-04T08:45:53.239+0000] {logging_mixin.py:188} WARNING -   File "/home/***/.local/lib/python3.12/site-packages/psycopg2/extras.py", line 1299, in execute_values
    cur.execute(b''.join(parts))
[2025-06-04T08:45:53.239+0000] {logging_mixin.py:188} WARNING - psycopg2.errors.UniqueViolation: duplicate key value violates unique constraint "drivers_pkey"
DETAIL:  Key (driver_id)=(max_verstappen) already exists.
[2025-06-04T08:45:53.239+0000] {logging_mixin.py:188} WARNING - 
The above exception was the direct cause of the following exception:
[2025-06-04T08:45:53.239+0000] {logging_mixin.py:188} WARNING - Traceback (most recent call last):
[2025-06-04T08:45:53.240+0000] {logging_mixin.py:188} WARNING -   File "/opt/***/plugins/etl_scripts/load_to_postgres.py", line 42, in _load_single_csv_to_db
    df.to_sql(name=table_name, con=engine, if_exists='append', index=False, schema='public')
[2025-06-04T08:45:53.240+0000] {logging_mixin.py:188} WARNING -   File "/home/***/.local/lib/python3.12/site-packages/pandas/util/_decorators.py", line 333, in wrapper
    return func(*args, **kwargs)
           ^^^^^^^^^^^^^^^^^^^^^
[2025-06-04T08:45:53.240+0000] {logging_mixin.py:188} WARNING -   File "/home/***/.local/lib/python3.12/site-packages/pandas/core/generic.py", line 3008, in to_sql
    return sql.to_sql(
           ^^^^^^^^^^^
[2025-06-04T08:45:53.240+0000] {logging_mixin.py:188} WARNING -   File "/home/***/.local/lib/python3.12/site-packages/pandas/io/sql.py", line 788, in to_sql
    return pandas_sql.to_sql(
           ^^^^^^^^^^^^^^^^^^
[2025-06-04T08:45:53.240+0000] {logging_mixin.py:188} WARNING -   File "/home/***/.local/lib/python3.12/site-packages/pandas/io/sql.py", line 1958, in to_sql
    total_inserted = sql_engine.insert_records(
                     ^^^^^^^^^^^^^^^^^^^^^^^^^^
[2025-06-04T08:45:53.240+0000] {logging_mixin.py:188} WARNING -   File "/home/***/.local/lib/python3.12/site-packages/pandas/io/sql.py", line 1507, in insert_records
    raise err
[2025-06-04T08:45:53.240+0000] {logging_mixin.py:188} WARNING -   File "/home/***/.local/lib/python3.12/site-packages/pandas/io/sql.py", line 1498, in insert_records
    return table.insert(chunksize=chunksize, method=method)
           ^^^^^^^^^^^^^^^^^^^^^^^^^^^^^^^^^^^^^^^^^^^^^^^^
[2025-06-04T08:45:53.240+0000] {logging_mixin.py:188} WARNING -   File "/home/***/.local/lib/python3.12/site-packages/pandas/io/sql.py", line 1059, in insert
    num_inserted = exec_insert(conn, keys, chunk_iter)
                   ^^^^^^^^^^^^^^^^^^^^^^^^^^^^^^^^^^^
[2025-06-04T08:45:53.241+0000] {logging_mixin.py:188} WARNING -   File "/home/***/.local/lib/python3.12/site-packages/pandas/io/sql.py", line 951, in _execute_insert
    result = conn.execute(self.table.insert(), data)
             ^^^^^^^^^^^^^^^^^^^^^^^^^^^^^^^^^^^^^^^
[2025-06-04T08:45:53.241+0000] {logging_mixin.py:188} WARNING -   File "/home/***/.local/lib/python3.12/site-packages/sqlalchemy/engine/base.py", line 1385, in execute
    return meth(self, multiparams, params, _EMPTY_EXECUTION_OPTS)
           ^^^^^^^^^^^^^^^^^^^^^^^^^^^^^^^^^^^^^^^^^^^^^^^^^^^^^^
[2025-06-04T08:45:53.241+0000] {logging_mixin.py:188} WARNING -   File "/home/***/.local/lib/python3.12/site-packages/sqlalchemy/sql/elements.py", line 334, in _execute_on_connection
    return connection._execute_clauseelement(
           ^^^^^^^^^^^^^^^^^^^^^^^^^^^^^^^^^^
[2025-06-04T08:45:53.241+0000] {logging_mixin.py:188} WARNING -   File "/home/***/.local/lib/python3.12/site-packages/sqlalchemy/engine/base.py", line 1577, in _execute_clauseelement
    ret = self._execute_context(
          ^^^^^^^^^^^^^^^^^^^^^^
[2025-06-04T08:45:53.241+0000] {logging_mixin.py:188} WARNING -   File "/home/***/.local/lib/python3.12/site-packages/sqlalchemy/engine/base.py", line 1953, in _execute_context
    self._handle_dbapi_exception(
[2025-06-04T08:45:53.241+0000] {logging_mixin.py:188} WARNING -   File "/home/***/.local/lib/python3.12/site-packages/sqlalchemy/engine/base.py", line 2134, in _handle_dbapi_exception
    util.raise_(
[2025-06-04T08:45:53.241+0000] {logging_mixin.py:188} WARNING -   File "/home/***/.local/lib/python3.12/site-packages/sqlalchemy/util/compat.py", line 211, in raise_
    raise exception
[2025-06-04T08:45:53.241+0000] {logging_mixin.py:188} WARNING -   File "/home/***/.local/lib/python3.12/site-packages/sqlalchemy/engine/base.py", line 1890, in _execute_context
    self.dialect.do_executemany(
[2025-06-04T08:45:53.241+0000] {logging_mixin.py:188} WARNING -   File "/home/***/.local/lib/python3.12/site-packages/sqlalchemy/dialects/postgresql/psycopg2.py", line 982, in do_executemany
    context._psycopg2_fetched_rows = xtras.execute_values(
                                     ^^^^^^^^^^^^^^^^^^^^^
[2025-06-04T08:45:53.241+0000] {logging_mixin.py:188} WARNING -   File "/home/***/.local/lib/python3.12/site-packages/psycopg2/extras.py", line 1299, in execute_values
    cur.execute(b''.join(parts))
[2025-06-04T08:45:53.242+0000] {logging_mixin.py:188} WARNING - sqlalchemy.exc.IntegrityError: (psycopg2.errors.UniqueViolation) duplicate key value violates unique constraint "drivers_pkey"
DETAIL:  Key (driver_id)=(max_verstappen) already exists.

[SQL: INSERT INTO public.drivers (driver_id, permanent_number, code, given_name, family_name, date_of_birth, nationality) VALUES (%(driver_id)s, %(permanent_number)s, %(code)s, %(given_name)s, %(family_name)s, %(date_of_birth)s, %(nationality)s)]
[parameters: ({'driver_id': 'max_verstappen', 'permanent_number': 33, 'code': 'VER', 'given_name': 'Max', 'family_name': 'Verstappen', 'date_of_birth': '1997-09-30', 'nationality': 'Dutch'}, {'driver_id': 'perez', 'permanent_number': 11, 'code': 'PER', 'given_name': 'Sergio', 'family_name': 'Pérez', 'date_of_birth': '1990-01-26', 'nationality': 'Mexican'}, {'driver_id': 'sainz', 'permanent_number': 55, 'code': 'SAI', 'given_name': 'Carlos', 'family_name': 'Sainz', 'date_of_birth': '1994-09-01', 'nationality': 'Spanish'}, {'driver_id': 'leclerc', 'permanent_number': 16, 'code': 'LEC', 'given_name': 'Charles', 'family_name': 'Leclerc', 'date_of_birth': '1997-10-16', 'nationality': 'Monegasque'}, {'driver_id': 'russell', 'permanent_number': 63, 'code': 'RUS', 'given_name': 'George', 'family_name': 'Russell', 'date_of_birth': '1998-02-15', 'nationality': 'British'}, {'driver_id': 'norris', 'permanent_number': 4, 'code': 'NOR', 'given_name': 'Lando', 'family_name': 'Norris', 'date_of_birth': '1999-11-13', 'nationality': 'British'}, {'driver_id': 'hamilton', 'permanent_number': 44, 'code': 'HAM', 'given_name': 'Lewis', 'family_name': 'Hamilton', 'date_of_birth': '1985-01-07', 'nationality': 'British'}, {'driver_id': 'piastri', 'permanent_number': 81, 'code': 'PIA', 'given_name': 'Oscar', 'family_name': 'Piastri', 'date_of_birth': '2001-04-06', 'nationality': 'Australian'}  ... displaying 10 of 21 total bound parameter sets ...  {'driver_id': 'sargeant', 'permanent_number': 2, 'code': 'SAR', 'given_name': 'Logan', 'family_name': 'Sargeant', 'date_of_birth': '2000-12-31', 'nationality': 'American'}, {'driver_id': 'bearman', 'permanent_number': 38, 'code': 'BEA', 'given_name': 'Oliver', 'family_name': 'Bearman', 'date_of_birth': '2005-05-08', 'nationality': 'British'})]
(Background on this error at: https://sqlalche.me/e/14/gkpj)
[2025-06-04T08:45:53.242+0000] {logging_mixin.py:188} INFO - --- Résultat pour drivers.csv: ÉCHEC ---
[2025-06-04T08:45:53.242+0000] {logging_mixin.py:188} INFO - 
--- Début du traitement pour constructors.csv vers table constructors ---
[2025-06-04T08:45:53.246+0000] {base.py:84} INFO - Using connection ID 'f1_postgres_db' for task execution.
[2025-06-04T08:45:53.252+0000] {logging_mixin.py:188} INFO - Erreur générique non attrapée spécifiquement lors du chargement de /opt/***/data/processed/2024/constructors.csv vers la table constructors:
[2025-06-04T08:45:53.252+0000] {logging_mixin.py:188} WARNING - Traceback (most recent call last):
[2025-06-04T08:45:53.252+0000] {logging_mixin.py:188} WARNING -   File "/home/***/.local/lib/python3.12/site-packages/sqlalchemy/engine/base.py", line 1890, in _execute_context
    self.dialect.do_executemany(
[2025-06-04T08:45:53.253+0000] {logging_mixin.py:188} WARNING -   File "/home/***/.local/lib/python3.12/site-packages/sqlalchemy/dialects/postgresql/psycopg2.py", line 982, in do_executemany
    context._psycopg2_fetched_rows = xtras.execute_values(
                                     ^^^^^^^^^^^^^^^^^^^^^
[2025-06-04T08:45:53.253+0000] {logging_mixin.py:188} WARNING -   File "/home/***/.local/lib/python3.12/site-packages/psycopg2/extras.py", line 1299, in execute_values
    cur.execute(b''.join(parts))
[2025-06-04T08:45:53.253+0000] {logging_mixin.py:188} WARNING - psycopg2.errors.UniqueViolation: duplicate key value violates unique constraint "constructors_pkey"
DETAIL:  Key (constructor_id)=(red_bull) already exists.
[2025-06-04T08:45:53.253+0000] {logging_mixin.py:188} WARNING - 
The above exception was the direct cause of the following exception:
[2025-06-04T08:45:53.253+0000] {logging_mixin.py:188} WARNING - Traceback (most recent call last):
[2025-06-04T08:45:53.253+0000] {logging_mixin.py:188} WARNING -   File "/opt/***/plugins/etl_scripts/load_to_postgres.py", line 42, in _load_single_csv_to_db
    df.to_sql(name=table_name, con=engine, if_exists='append', index=False, schema='public')
[2025-06-04T08:45:53.253+0000] {logging_mixin.py:188} WARNING -   File "/home/***/.local/lib/python3.12/site-packages/pandas/util/_decorators.py", line 333, in wrapper
    return func(*args, **kwargs)
           ^^^^^^^^^^^^^^^^^^^^^
[2025-06-04T08:45:53.254+0000] {logging_mixin.py:188} WARNING -   File "/home/***/.local/lib/python3.12/site-packages/pandas/core/generic.py", line 3008, in to_sql
    return sql.to_sql(
           ^^^^^^^^^^^
[2025-06-04T08:45:53.254+0000] {logging_mixin.py:188} WARNING -   File "/home/***/.local/lib/python3.12/site-packages/pandas/io/sql.py", line 788, in to_sql
    return pandas_sql.to_sql(
           ^^^^^^^^^^^^^^^^^^
[2025-06-04T08:45:53.254+0000] {logging_mixin.py:188} WARNING -   File "/home/***/.local/lib/python3.12/site-packages/pandas/io/sql.py", line 1958, in to_sql
    total_inserted = sql_engine.insert_records(
                     ^^^^^^^^^^^^^^^^^^^^^^^^^^
[2025-06-04T08:45:53.254+0000] {logging_mixin.py:188} WARNING -   File "/home/***/.local/lib/python3.12/site-packages/pandas/io/sql.py", line 1507, in insert_records
    raise err
[2025-06-04T08:45:53.254+0000] {logging_mixin.py:188} WARNING -   File "/home/***/.local/lib/python3.12/site-packages/pandas/io/sql.py", line 1498, in insert_records
    return table.insert(chunksize=chunksize, method=method)
           ^^^^^^^^^^^^^^^^^^^^^^^^^^^^^^^^^^^^^^^^^^^^^^^^
[2025-06-04T08:45:53.254+0000] {logging_mixin.py:188} WARNING -   File "/home/***/.local/lib/python3.12/site-packages/pandas/io/sql.py", line 1059, in insert
    num_inserted = exec_insert(conn, keys, chunk_iter)
                   ^^^^^^^^^^^^^^^^^^^^^^^^^^^^^^^^^^^
[2025-06-04T08:45:53.254+0000] {logging_mixin.py:188} WARNING -   File "/home/***/.local/lib/python3.12/site-packages/pandas/io/sql.py", line 951, in _execute_insert
    result = conn.execute(self.table.insert(), data)
             ^^^^^^^^^^^^^^^^^^^^^^^^^^^^^^^^^^^^^^^
[2025-06-04T08:45:53.254+0000] {logging_mixin.py:188} WARNING -   File "/home/***/.local/lib/python3.12/site-packages/sqlalchemy/engine/base.py", line 1385, in execute
    return meth(self, multiparams, params, _EMPTY_EXECUTION_OPTS)
           ^^^^^^^^^^^^^^^^^^^^^^^^^^^^^^^^^^^^^^^^^^^^^^^^^^^^^^
[2025-06-04T08:45:53.254+0000] {logging_mixin.py:188} WARNING -   File "/home/***/.local/lib/python3.12/site-packages/sqlalchemy/sql/elements.py", line 334, in _execute_on_connection
    return connection._execute_clauseelement(
           ^^^^^^^^^^^^^^^^^^^^^^^^^^^^^^^^^^
[2025-06-04T08:45:53.254+0000] {logging_mixin.py:188} WARNING -   File "/home/***/.local/lib/python3.12/site-packages/sqlalchemy/engine/base.py", line 1577, in _execute_clauseelement
    ret = self._execute_context(
          ^^^^^^^^^^^^^^^^^^^^^^
[2025-06-04T08:45:53.254+0000] {logging_mixin.py:188} WARNING -   File "/home/***/.local/lib/python3.12/site-packages/sqlalchemy/engine/base.py", line 1953, in _execute_context
    self._handle_dbapi_exception(
[2025-06-04T08:45:53.255+0000] {logging_mixin.py:188} WARNING -   File "/home/***/.local/lib/python3.12/site-packages/sqlalchemy/engine/base.py", line 2134, in _handle_dbapi_exception
    util.raise_(
[2025-06-04T08:45:53.255+0000] {logging_mixin.py:188} WARNING -   File "/home/***/.local/lib/python3.12/site-packages/sqlalchemy/util/compat.py", line 211, in raise_
    raise exception
[2025-06-04T08:45:53.255+0000] {logging_mixin.py:188} WARNING -   File "/home/***/.local/lib/python3.12/site-packages/sqlalchemy/engine/base.py", line 1890, in _execute_context
    self.dialect.do_executemany(
[2025-06-04T08:45:53.255+0000] {logging_mixin.py:188} WARNING -   File "/home/***/.local/lib/python3.12/site-packages/sqlalchemy/dialects/postgresql/psycopg2.py", line 982, in do_executemany
    context._psycopg2_fetched_rows = xtras.execute_values(
                                     ^^^^^^^^^^^^^^^^^^^^^
[2025-06-04T08:45:53.255+0000] {logging_mixin.py:188} WARNING -   File "/home/***/.local/lib/python3.12/site-packages/psycopg2/extras.py", line 1299, in execute_values
    cur.execute(b''.join(parts))
[2025-06-04T08:45:53.255+0000] {logging_mixin.py:188} WARNING - sqlalchemy.exc.IntegrityError: (psycopg2.errors.UniqueViolation) duplicate key value violates unique constraint "constructors_pkey"
DETAIL:  Key (constructor_id)=(red_bull) already exists.

[SQL: INSERT INTO public.constructors (constructor_id, name, nationality) VALUES (%(constructor_id)s, %(name)s, %(nationality)s)]
[parameters: ({'constructor_id': 'red_bull', 'name': 'Red Bull', 'nationality': 'Austrian'}, {'constructor_id': 'ferrari', 'name': 'Ferrari', 'nationality': 'Italian'}, {'constructor_id': 'mercedes', 'name': 'Mercedes', 'nationality': 'German'}, {'constructor_id': 'mclaren', 'name': 'McLaren', 'nationality': 'British'}, {'constructor_id': 'aston_martin', 'name': 'Aston Martin', 'nationality': 'British'}, {'constructor_id': 'sauber', 'name': 'Sauber', 'nationality': 'Swiss'}, {'constructor_id': 'haas', 'name': 'Haas F1 Team', 'nationality': 'American'}, {'constructor_id': 'rb', 'name': 'RB F1 Team', 'nationality': 'Italian'}, {'constructor_id': 'williams', 'name': 'Williams', 'nationality': 'British'}, {'constructor_id': 'alpine', 'name': 'Alpine F1 Team', 'nationality': 'French'})]
(Background on this error at: https://sqlalche.me/e/14/gkpj)
[2025-06-04T08:45:53.255+0000] {logging_mixin.py:188} INFO - --- Résultat pour constructors.csv: ÉCHEC ---
[2025-06-04T08:45:53.255+0000] {logging_mixin.py:188} INFO - 
--- Début du traitement pour races_schedule.csv vers table races ---
[2025-06-04T08:45:53.260+0000] {base.py:84} INFO - Using connection ID 'f1_postgres_db' for task execution.
[2025-06-04T08:45:53.266+0000] {logging_mixin.py:188} INFO - Données de /opt/***/data/processed/2024/races_schedule.csv chargées avec succès dans la table races.
[2025-06-04T08:45:53.267+0000] {logging_mixin.py:188} INFO - --- Résultat pour races_schedule.csv: Succès ---
[2025-06-04T08:45:53.267+0000] {logging_mixin.py:188} INFO - 
--- Début du traitement pour detailed_results.csv vers table results ---
[2025-06-04T08:45:53.272+0000] {base.py:84} INFO - Using connection ID 'f1_postgres_db' for task execution.
[2025-06-04T08:45:53.284+0000] {logging_mixin.py:188} INFO - Données de /opt/***/data/processed/2024/detailed_results.csv chargées avec succès dans la table results.
[2025-06-04T08:45:53.284+0000] {logging_mixin.py:188} INFO - --- Résultat pour detailed_results.csv: Succès ---
[2025-06-04T08:45:53.284+0000] {logging_mixin.py:188} INFO - 
Valeur finale de overall_success avant le check: False
[2025-06-04T08:45:53.284+0000] {logging_mixin.py:188} INFO - overall_success est False, levée de ValueError.
[2025-06-04T08:45:53.284+0000] {taskinstance.py:441} INFO - ::group::Post task execution logs
[2025-06-04T08:45:53.284+0000] {taskinstance.py:2905} ERROR - Task failed with exception
Traceback (most recent call last):
  File "/home/airflow/.local/lib/python3.12/site-packages/airflow/models/taskinstance.py", line 465, in _execute_task
    result = _execute_callable(context=context, **execute_callable_kwargs)
             ^^^^^^^^^^^^^^^^^^^^^^^^^^^^^^^^^^^^^^^^^^^^^^^^^^^^^^^^^^^^^
  File "/home/airflow/.local/lib/python3.12/site-packages/airflow/models/taskinstance.py", line 432, in _execute_callable
    return execute_callable(context=context, **execute_callable_kwargs)
           ^^^^^^^^^^^^^^^^^^^^^^^^^^^^^^^^^^^^^^^^^^^^^^^^^^^^^^^^^^^^
  File "/home/airflow/.local/lib/python3.12/site-packages/airflow/models/baseoperator.py", line 401, in wrapper
    return func(self, *args, **kwargs)
           ^^^^^^^^^^^^^^^^^^^^^^^^^^^
  File "/home/airflow/.local/lib/python3.12/site-packages/airflow/operators/python.py", line 235, in execute
    return_value = self.execute_callable()
                   ^^^^^^^^^^^^^^^^^^^^^^^
  File "/home/airflow/.local/lib/python3.12/site-packages/airflow/operators/python.py", line 252, in execute_callable
    return self.python_callable(*self.op_args, **self.op_kwargs)
           ^^^^^^^^^^^^^^^^^^^^^^^^^^^^^^^^^^^^^^^^^^^^^^^^^^^^^
  File "/opt/airflow/plugins/etl_scripts/load_to_postgres.py", line 118, in load_all_processed_data_to_postgres
    raise ValueError(f"Un ou plusieurs chargements en base de données ont échoué pour l'année {year}.")
ValueError: Un ou plusieurs chargements en base de données ont échoué pour l'année 2024.
[2025-06-04T08:45:53.289+0000] {taskinstance.py:1206} INFO - Marking task as FAILED. dag_id=f1_data_extraction_pipeline, task_id=load_data_to_postgres, run_id=manual__2025-06-04T08:45:40+00:00, execution_date=20250604T084540, start_date=20250604T084552, end_date=20250604T084553
[2025-06-04T08:45:53.293+0000] {standard_task_runner.py:110} ERROR - Failed to execute job 21 for task load_data_to_postgres (Un ou plusieurs chargements en base de données ont échoué pour l'année 2024.; 395)
[2025-06-04T08:45:53.331+0000] {local_task_job_runner.py:240} INFO - Task exited with return code 1
[2025-06-04T08:45:53.338+0000] {taskinstance.py:3503} INFO - 0 downstream tasks scheduled from follow-on schedule check
[2025-06-04T08:45:53.339+0000] {local_task_job_runner.py:222} INFO - ::endgroup::
