[2025-06-03T18:51:17.079+0000] {local_task_job_runner.py:120} INFO - ::group::Pre task execution logs
[2025-06-03T18:51:17.093+0000] {taskinstance.py:2076} INFO - Dependencies all met for dep_context=non-requeueable deps ti=<TaskInstance: f1_data_extraction_pipeline.load_data_to_postgres manual__2025-06-03T18:51:07+00:00 [queued]>
[2025-06-03T18:51:17.096+0000] {taskinstance.py:2076} INFO - Dependencies all met for dep_context=requeueable deps ti=<TaskInstance: f1_data_extraction_pipeline.load_data_to_postgres manual__2025-06-03T18:51:07+00:00 [queued]>
[2025-06-03T18:51:17.096+0000] {taskinstance.py:2306} INFO - Starting attempt 1 of 1
[2025-06-03T18:51:17.101+0000] {taskinstance.py:2330} INFO - Executing <Task(PythonOperator): load_data_to_postgres> on 2025-06-03 18:51:07+00:00
[2025-06-03T18:51:17.105+0000] {standard_task_runner.py:90} INFO - Running: ['***', 'tasks', 'run', 'f1_data_extraction_pipeline', 'load_data_to_postgres', 'manual__2025-06-03T18:51:07+00:00', '--job-id', '55', '--raw', '--subdir', 'DAGS_FOLDER/f1_pipeline.py', '--cfg-path', '/tmp/tmpanv89wm_']
[2025-06-03T18:51:17.110+0000] {standard_task_runner.py:91} INFO - Job 55: Subtask load_data_to_postgres
[2025-06-03T18:51:17.210+0000] {logging_mixin.py:188} WARNING - /home/***/.local/lib/python3.12/site-packages/***/task/task_runner/standard_task_runner.py:61 DeprecationWarning: This process (pid=321) is multi-threaded, use of fork() may lead to deadlocks in the child.
[2025-06-03T18:51:17.212+0000] {standard_task_runner.py:63} INFO - Started process 322 to run task
[2025-06-03T18:51:17.227+0000] {task_command.py:426} INFO - Running <TaskInstance: f1_data_extraction_pipeline.load_data_to_postgres manual__2025-06-03T18:51:07+00:00 [running]> on host 272d0a595586
[2025-06-03T18:51:17.260+0000] {taskinstance.py:2648} INFO - Exporting env vars: AIRFLOW_CTX_DAG_OWNER='***' AIRFLOW_CTX_DAG_ID='f1_data_extraction_pipeline' AIRFLOW_CTX_TASK_ID='load_data_to_postgres' AIRFLOW_CTX_EXECUTION_DATE='2025-06-03T18:51:07+00:00' AIRFLOW_CTX_TRY_NUMBER='1' AIRFLOW_CTX_DAG_RUN_ID='manual__2025-06-03T18:51:07+00:00'
[2025-06-03T18:51:17.260+0000] {taskinstance.py:430} INFO - ::endgroup::
[2025-06-03T18:51:17.264+0000] {logging_mixin.py:188} INFO - Début du chargement en base de données pour l'année 2024.
[2025-06-03T18:51:17.264+0000] {logging_mixin.py:188} INFO - Fichier CSV non trouvé : /opt/***/data/processed/2024/circuits_info.csv. Chargement sauté pour la table circuits.
[2025-06-03T18:51:17.273+0000] {logging_mixin.py:188} INFO - Erreur lors du chargement de /opt/***/data/processed/2024/drivers.csv vers la table drivers:
[2025-06-03T18:51:17.274+0000] {logging_mixin.py:188} WARNING - Traceback (most recent call last):
[2025-06-03T18:51:17.274+0000] {logging_mixin.py:188} WARNING -   File "/opt/***/plugins/etl_scripts/load_to_postgres.py", line 39, in _load_single_csv_to_db
    engine = pg_hook.get_sqlalchemy_engine()
             ^^^^^^^^^^^^^^^^^^^^^^^^^^^^^^^
[2025-06-03T18:51:17.274+0000] {logging_mixin.py:188} WARNING -   File "/home/***/.local/lib/python3.12/site-packages/***/providers/common/sql/hooks/sql.py", line 239, in get_sqlalchemy_engine
    return create_engine(self.get_uri(), **engine_kwargs)
                         ^^^^^^^^^^^^^^
[2025-06-03T18:51:17.274+0000] {logging_mixin.py:188} WARNING -   File "/home/***/.local/lib/python3.12/site-packages/***/providers/postgres/hooks/postgres.py", line 204, in get_uri
    return self.sqlalchemy_url.render_as_string(hide_password=False)
           ^^^^^^^^^^^^^^^^^^^
[2025-06-03T18:51:17.274+0000] {logging_mixin.py:188} WARNING -   File "/home/***/.local/lib/python3.12/site-packages/***/providers/postgres/hooks/postgres.py", line 119, in sqlalchemy_url
    conn = self.get_connection(getattr(self, self.conn_name_attr))
           ^^^^^^^^^^^^^^^^^^^^^^^^^^^^^^^^^^^^^^^^^^^^^^^^^^^^^^^
[2025-06-03T18:51:17.274+0000] {logging_mixin.py:188} WARNING -   File "/home/***/.local/lib/python3.12/site-packages/***/hooks/base.py", line 83, in get_connection
    conn = Connection.get_connection_from_secrets(conn_id)
           ^^^^^^^^^^^^^^^^^^^^^^^^^^^^^^^^^^^^^^^^^^^^^^^
[2025-06-03T18:51:17.274+0000] {logging_mixin.py:188} WARNING -   File "/home/***/.local/lib/python3.12/site-packages/***/models/connection.py", line 519, in get_connection_from_secrets
    raise AirflowNotFoundException(f"The conn_id `{conn_id}` isn't defined")
[2025-06-03T18:51:17.274+0000] {logging_mixin.py:188} WARNING - ***.exceptions.AirflowNotFoundException: The conn_id `f1_postgres_db` isn't defined
[2025-06-03T18:51:17.274+0000] {logging_mixin.py:188} INFO - Échec du chargement pour drivers. Poursuite avec les autres tables si possible.
[2025-06-03T18:51:17.278+0000] {logging_mixin.py:188} INFO - Erreur lors du chargement de /opt/***/data/processed/2024/constructors.csv vers la table constructors:
[2025-06-03T18:51:17.278+0000] {logging_mixin.py:188} WARNING - Traceback (most recent call last):
[2025-06-03T18:51:17.278+0000] {logging_mixin.py:188} WARNING -   File "/opt/***/plugins/etl_scripts/load_to_postgres.py", line 39, in _load_single_csv_to_db
    engine = pg_hook.get_sqlalchemy_engine()
             ^^^^^^^^^^^^^^^^^^^^^^^^^^^^^^^
[2025-06-03T18:51:17.278+0000] {logging_mixin.py:188} WARNING -   File "/home/***/.local/lib/python3.12/site-packages/***/providers/common/sql/hooks/sql.py", line 239, in get_sqlalchemy_engine
    return create_engine(self.get_uri(), **engine_kwargs)
                         ^^^^^^^^^^^^^^
[2025-06-03T18:51:17.279+0000] {logging_mixin.py:188} WARNING -   File "/home/***/.local/lib/python3.12/site-packages/***/providers/postgres/hooks/postgres.py", line 204, in get_uri
    return self.sqlalchemy_url.render_as_string(hide_password=False)
           ^^^^^^^^^^^^^^^^^^^
[2025-06-03T18:51:17.279+0000] {logging_mixin.py:188} WARNING -   File "/home/***/.local/lib/python3.12/site-packages/***/providers/postgres/hooks/postgres.py", line 119, in sqlalchemy_url
    conn = self.get_connection(getattr(self, self.conn_name_attr))
           ^^^^^^^^^^^^^^^^^^^^^^^^^^^^^^^^^^^^^^^^^^^^^^^^^^^^^^^
[2025-06-03T18:51:17.279+0000] {logging_mixin.py:188} WARNING -   File "/home/***/.local/lib/python3.12/site-packages/***/hooks/base.py", line 83, in get_connection
    conn = Connection.get_connection_from_secrets(conn_id)
           ^^^^^^^^^^^^^^^^^^^^^^^^^^^^^^^^^^^^^^^^^^^^^^^
[2025-06-03T18:51:17.279+0000] {logging_mixin.py:188} WARNING -   File "/home/***/.local/lib/python3.12/site-packages/***/models/connection.py", line 519, in get_connection_from_secrets
    raise AirflowNotFoundException(f"The conn_id `{conn_id}` isn't defined")
[2025-06-03T18:51:17.279+0000] {logging_mixin.py:188} WARNING - ***.exceptions.AirflowNotFoundException: The conn_id `f1_postgres_db` isn't defined
[2025-06-03T18:51:17.279+0000] {logging_mixin.py:188} INFO - Échec du chargement pour constructors. Poursuite avec les autres tables si possible.
[2025-06-03T18:51:17.283+0000] {logging_mixin.py:188} INFO - Erreur lors du chargement de /opt/***/data/processed/2024/races_schedule.csv vers la table races:
[2025-06-03T18:51:17.283+0000] {logging_mixin.py:188} WARNING - Traceback (most recent call last):
[2025-06-03T18:51:17.283+0000] {logging_mixin.py:188} WARNING -   File "/opt/***/plugins/etl_scripts/load_to_postgres.py", line 39, in _load_single_csv_to_db
    engine = pg_hook.get_sqlalchemy_engine()
             ^^^^^^^^^^^^^^^^^^^^^^^^^^^^^^^
[2025-06-03T18:51:17.284+0000] {logging_mixin.py:188} WARNING -   File "/home/***/.local/lib/python3.12/site-packages/***/providers/common/sql/hooks/sql.py", line 239, in get_sqlalchemy_engine
    return create_engine(self.get_uri(), **engine_kwargs)
                         ^^^^^^^^^^^^^^
[2025-06-03T18:51:17.284+0000] {logging_mixin.py:188} WARNING -   File "/home/***/.local/lib/python3.12/site-packages/***/providers/postgres/hooks/postgres.py", line 204, in get_uri
    return self.sqlalchemy_url.render_as_string(hide_password=False)
           ^^^^^^^^^^^^^^^^^^^
[2025-06-03T18:51:17.284+0000] {logging_mixin.py:188} WARNING -   File "/home/***/.local/lib/python3.12/site-packages/***/providers/postgres/hooks/postgres.py", line 119, in sqlalchemy_url
    conn = self.get_connection(getattr(self, self.conn_name_attr))
           ^^^^^^^^^^^^^^^^^^^^^^^^^^^^^^^^^^^^^^^^^^^^^^^^^^^^^^^
[2025-06-03T18:51:17.284+0000] {logging_mixin.py:188} WARNING -   File "/home/***/.local/lib/python3.12/site-packages/***/hooks/base.py", line 83, in get_connection
    conn = Connection.get_connection_from_secrets(conn_id)
           ^^^^^^^^^^^^^^^^^^^^^^^^^^^^^^^^^^^^^^^^^^^^^^^
[2025-06-03T18:51:17.284+0000] {logging_mixin.py:188} WARNING -   File "/home/***/.local/lib/python3.12/site-packages/***/models/connection.py", line 519, in get_connection_from_secrets
    raise AirflowNotFoundException(f"The conn_id `{conn_id}` isn't defined")
[2025-06-03T18:51:17.284+0000] {logging_mixin.py:188} WARNING - ***.exceptions.AirflowNotFoundException: The conn_id `f1_postgres_db` isn't defined
[2025-06-03T18:51:17.284+0000] {logging_mixin.py:188} INFO - Échec du chargement pour races. Poursuite avec les autres tables si possible.
[2025-06-03T18:51:17.290+0000] {logging_mixin.py:188} INFO - Erreur lors du chargement de /opt/***/data/processed/2024/detailed_results.csv vers la table results:
[2025-06-03T18:51:17.290+0000] {logging_mixin.py:188} WARNING - Traceback (most recent call last):
[2025-06-03T18:51:17.291+0000] {logging_mixin.py:188} WARNING -   File "/opt/***/plugins/etl_scripts/load_to_postgres.py", line 39, in _load_single_csv_to_db
    engine = pg_hook.get_sqlalchemy_engine()
             ^^^^^^^^^^^^^^^^^^^^^^^^^^^^^^^
[2025-06-03T18:51:17.291+0000] {logging_mixin.py:188} WARNING -   File "/home/***/.local/lib/python3.12/site-packages/***/providers/common/sql/hooks/sql.py", line 239, in get_sqlalchemy_engine
    return create_engine(self.get_uri(), **engine_kwargs)
                         ^^^^^^^^^^^^^^
[2025-06-03T18:51:17.291+0000] {logging_mixin.py:188} WARNING -   File "/home/***/.local/lib/python3.12/site-packages/***/providers/postgres/hooks/postgres.py", line 204, in get_uri
    return self.sqlalchemy_url.render_as_string(hide_password=False)
           ^^^^^^^^^^^^^^^^^^^
[2025-06-03T18:51:17.291+0000] {logging_mixin.py:188} WARNING -   File "/home/***/.local/lib/python3.12/site-packages/***/providers/postgres/hooks/postgres.py", line 119, in sqlalchemy_url
    conn = self.get_connection(getattr(self, self.conn_name_attr))
           ^^^^^^^^^^^^^^^^^^^^^^^^^^^^^^^^^^^^^^^^^^^^^^^^^^^^^^^
[2025-06-03T18:51:17.291+0000] {logging_mixin.py:188} WARNING -   File "/home/***/.local/lib/python3.12/site-packages/***/hooks/base.py", line 83, in get_connection
    conn = Connection.get_connection_from_secrets(conn_id)
           ^^^^^^^^^^^^^^^^^^^^^^^^^^^^^^^^^^^^^^^^^^^^^^^
[2025-06-03T18:51:17.291+0000] {logging_mixin.py:188} WARNING -   File "/home/***/.local/lib/python3.12/site-packages/***/models/connection.py", line 519, in get_connection_from_secrets
    raise AirflowNotFoundException(f"The conn_id `{conn_id}` isn't defined")
[2025-06-03T18:51:17.291+0000] {logging_mixin.py:188} WARNING - ***.exceptions.AirflowNotFoundException: The conn_id `f1_postgres_db` isn't defined
[2025-06-03T18:51:17.291+0000] {logging_mixin.py:188} INFO - Échec du chargement pour results. Poursuite avec les autres tables si possible.
[2025-06-03T18:51:17.291+0000] {taskinstance.py:441} INFO - ::group::Post task execution logs
[2025-06-03T18:51:17.292+0000] {taskinstance.py:2905} ERROR - Task failed with exception
Traceback (most recent call last):
  File "/home/airflow/.local/lib/python3.12/site-packages/airflow/models/taskinstance.py", line 465, in _execute_task
    result = _execute_callable(context=context, **execute_callable_kwargs)
             ^^^^^^^^^^^^^^^^^^^^^^^^^^^^^^^^^^^^^^^^^^^^^^^^^^^^^^^^^^^^^
  File "/home/airflow/.local/lib/python3.12/site-packages/airflow/models/taskinstance.py", line 432, in _execute_callable
    return execute_callable(context=context, **execute_callable_kwargs)
           ^^^^^^^^^^^^^^^^^^^^^^^^^^^^^^^^^^^^^^^^^^^^^^^^^^^^^^^^^^^^
  File "/home/airflow/.local/lib/python3.12/site-packages/airflow/models/baseoperator.py", line 401, in wrapper
    return func(self, *args, **kwargs)
           ^^^^^^^^^^^^^^^^^^^^^^^^^^^
  File "/home/airflow/.local/lib/python3.12/site-packages/airflow/operators/python.py", line 235, in execute
    return_value = self.execute_callable()
                   ^^^^^^^^^^^^^^^^^^^^^^^
  File "/home/airflow/.local/lib/python3.12/site-packages/airflow/operators/python.py", line 252, in execute_callable
    return self.python_callable(*self.op_args, **self.op_kwargs)
           ^^^^^^^^^^^^^^^^^^^^^^^^^^^^^^^^^^^^^^^^^^^^^^^^^^^^^
  File "/opt/airflow/plugins/etl_scripts/load_to_postgres.py", line 92, in load_all_processed_data_to_postgres
    raise ValueError(f"Un ou plusieurs chargements en base de données ont échoué pour l'année {year}.")
ValueError: Un ou plusieurs chargements en base de données ont échoué pour l'année 2024.
[2025-06-03T18:51:17.295+0000] {taskinstance.py:1206} INFO - Marking task as FAILED. dag_id=f1_data_extraction_pipeline, task_id=load_data_to_postgres, run_id=manual__2025-06-03T18:51:07+00:00, execution_date=20250603T185107, start_date=20250603T185117, end_date=20250603T185117
[2025-06-03T18:51:17.299+0000] {standard_task_runner.py:110} ERROR - Failed to execute job 55 for task load_data_to_postgres (Un ou plusieurs chargements en base de données ont échoué pour l'année 2024.; 322)
[2025-06-03T18:51:17.311+0000] {local_task_job_runner.py:240} INFO - Task exited with return code 1
[2025-06-03T18:51:17.318+0000] {taskinstance.py:3503} INFO - 0 downstream tasks scheduled from follow-on schedule check
[2025-06-03T18:51:17.319+0000] {local_task_job_runner.py:222} INFO - ::endgroup::
