[2025-06-03T18:58:07.438+0000] {local_task_job_runner.py:120} INFO - ::group::Pre task execution logs
[2025-06-03T18:58:07.453+0000] {taskinstance.py:2076} INFO - Dependencies all met for dep_context=non-requeueable deps ti=<TaskInstance: f1_data_extraction_pipeline.load_data_to_postgres manual__2025-06-03T18:57:56+00:00 [queued]>
[2025-06-03T18:58:07.457+0000] {taskinstance.py:2076} INFO - Dependencies all met for dep_context=requeueable deps ti=<TaskInstance: f1_data_extraction_pipeline.load_data_to_postgres manual__2025-06-03T18:57:56+00:00 [queued]>
[2025-06-03T18:58:07.457+0000] {taskinstance.py:2306} INFO - Starting attempt 1 of 1
[2025-06-03T18:58:07.462+0000] {taskinstance.py:2330} INFO - Executing <Task(PythonOperator): load_data_to_postgres> on 2025-06-03 18:57:56+00:00
[2025-06-03T18:58:07.468+0000] {standard_task_runner.py:90} INFO - Running: ['***', 'tasks', 'run', 'f1_data_extraction_pipeline', 'load_data_to_postgres', 'manual__2025-06-03T18:57:56+00:00', '--job-id', '66', '--raw', '--subdir', 'DAGS_FOLDER/f1_pipeline.py', '--cfg-path', '/tmp/tmpt6v4_8sf']
[2025-06-03T18:58:07.474+0000] {standard_task_runner.py:91} INFO - Job 66: Subtask load_data_to_postgres
[2025-06-03T18:58:07.577+0000] {logging_mixin.py:188} WARNING - /home/***/.local/lib/python3.12/site-packages/***/task/task_runner/standard_task_runner.py:61 DeprecationWarning: This process (pid=203) is multi-threaded, use of fork() may lead to deadlocks in the child.
[2025-06-03T18:58:07.579+0000] {standard_task_runner.py:63} INFO - Started process 204 to run task
[2025-06-03T18:58:07.600+0000] {task_command.py:426} INFO - Running <TaskInstance: f1_data_extraction_pipeline.load_data_to_postgres manual__2025-06-03T18:57:56+00:00 [running]> on host 72000afa98a9
[2025-06-03T18:58:07.634+0000] {taskinstance.py:2648} INFO - Exporting env vars: AIRFLOW_CTX_DAG_OWNER='***' AIRFLOW_CTX_DAG_ID='f1_data_extraction_pipeline' AIRFLOW_CTX_TASK_ID='load_data_to_postgres' AIRFLOW_CTX_EXECUTION_DATE='2025-06-03T18:57:56+00:00' AIRFLOW_CTX_TRY_NUMBER='1' AIRFLOW_CTX_DAG_RUN_ID='manual__2025-06-03T18:57:56+00:00'
[2025-06-03T18:58:07.635+0000] {taskinstance.py:430} INFO - ::endgroup::
[2025-06-03T18:58:07.639+0000] {logging_mixin.py:188} INFO - Début du chargement en base de données pour l'année 2024.
[2025-06-03T18:58:07.639+0000] {logging_mixin.py:188} INFO - Fichier CSV non trouvé : /opt/***/data/processed/2024/circuits_info.csv. Chargement sauté pour la table circuits.
[2025-06-03T18:58:07.652+0000] {base.py:84} INFO - Using connection ID 'f1_postgres_db' for task execution.
[2025-06-03T18:58:07.663+0000] {logging_mixin.py:188} INFO - Données de /opt/***/data/processed/2024/drivers.csv chargées avec succès dans la table drivers.
[2025-06-03T18:58:07.667+0000] {base.py:84} INFO - Using connection ID 'f1_postgres_db' for task execution.
[2025-06-03T18:58:07.672+0000] {logging_mixin.py:188} INFO - Données de /opt/***/data/processed/2024/constructors.csv chargées avec succès dans la table constructors.
[2025-06-03T18:58:07.676+0000] {base.py:84} INFO - Using connection ID 'f1_postgres_db' for task execution.
[2025-06-03T18:58:07.677+0000] {logging_mixin.py:188} INFO - Exécution : DELETE FROM races WHERE year = 2024;
[2025-06-03T18:58:07.680+0000] {base.py:84} INFO - Using connection ID 'f1_postgres_db' for task execution.
[2025-06-03T18:58:07.682+0000] {sql.py:487} INFO - Running statement: DELETE FROM races WHERE year = 2024;, parameters: None
[2025-06-03T18:58:07.682+0000] {logging_mixin.py:188} INFO - Erreur lors du chargement de /opt/***/data/processed/2024/races_schedule.csv vers la table races:
[2025-06-03T18:58:07.683+0000] {logging_mixin.py:188} WARNING - Traceback (most recent call last):
[2025-06-03T18:58:07.684+0000] {logging_mixin.py:188} WARNING -   File "/opt/***/plugins/etl_scripts/load_to_postgres.py", line 45, in _load_single_csv_to_db
    pg_hook.run(delete_sql)
[2025-06-03T18:58:07.684+0000] {logging_mixin.py:188} WARNING -   File "/home/***/.local/lib/python3.12/site-packages/***/providers/common/sql/hooks/sql.py", line 435, in run
    self._run_command(cur, sql_statement, parameters)
[2025-06-03T18:58:07.684+0000] {logging_mixin.py:188} WARNING -   File "/home/***/.local/lib/python3.12/site-packages/***/providers/common/sql/hooks/sql.py", line 492, in _run_command
    cur.execute(sql_statement)
[2025-06-03T18:58:07.684+0000] {logging_mixin.py:188} WARNING - psycopg2.errors.UndefinedTable: relation "races" does not exist
LINE 1: DELETE FROM races WHERE year = 2024;
                    ^
[2025-06-03T18:58:07.684+0000] {logging_mixin.py:188} INFO - Échec du chargement pour races. Poursuite avec les autres tables si possible.
[2025-06-03T18:58:07.689+0000] {base.py:84} INFO - Using connection ID 'f1_postgres_db' for task execution.
[2025-06-03T18:58:07.690+0000] {logging_mixin.py:188} INFO - Exécution : DELETE FROM results WHERE race_id LIKE '2024_%';
[2025-06-03T18:58:07.693+0000] {base.py:84} INFO - Using connection ID 'f1_postgres_db' for task execution.
[2025-06-03T18:58:07.695+0000] {sql.py:487} INFO - Running statement: DELETE FROM results WHERE race_id LIKE '2024_%';, parameters: None
[2025-06-03T18:58:07.695+0000] {logging_mixin.py:188} INFO - Erreur lors du chargement de /opt/***/data/processed/2024/detailed_results.csv vers la table results:
[2025-06-03T18:58:07.696+0000] {logging_mixin.py:188} WARNING - Traceback (most recent call last):
[2025-06-03T18:58:07.696+0000] {logging_mixin.py:188} WARNING -   File "/opt/***/plugins/etl_scripts/load_to_postgres.py", line 49, in _load_single_csv_to_db
    pg_hook.run(delete_sql)
[2025-06-03T18:58:07.696+0000] {logging_mixin.py:188} WARNING -   File "/home/***/.local/lib/python3.12/site-packages/***/providers/common/sql/hooks/sql.py", line 435, in run
    self._run_command(cur, sql_statement, parameters)
[2025-06-03T18:58:07.696+0000] {logging_mixin.py:188} WARNING -   File "/home/***/.local/lib/python3.12/site-packages/***/providers/common/sql/hooks/sql.py", line 492, in _run_command
    cur.execute(sql_statement)
[2025-06-03T18:58:07.696+0000] {logging_mixin.py:188} WARNING - psycopg2.errors.UndefinedTable: relation "results" does not exist
LINE 1: DELETE FROM results WHERE race_id LIKE '2024_%';
                    ^
[2025-06-03T18:58:07.696+0000] {logging_mixin.py:188} INFO - Échec du chargement pour results. Poursuite avec les autres tables si possible.
[2025-06-03T18:58:07.697+0000] {taskinstance.py:441} INFO - ::group::Post task execution logs
[2025-06-03T18:58:07.697+0000] {taskinstance.py:2905} ERROR - Task failed with exception
Traceback (most recent call last):
  File "/home/airflow/.local/lib/python3.12/site-packages/airflow/models/taskinstance.py", line 465, in _execute_task
    result = _execute_callable(context=context, **execute_callable_kwargs)
             ^^^^^^^^^^^^^^^^^^^^^^^^^^^^^^^^^^^^^^^^^^^^^^^^^^^^^^^^^^^^^
  File "/home/airflow/.local/lib/python3.12/site-packages/airflow/models/taskinstance.py", line 432, in _execute_callable
    return execute_callable(context=context, **execute_callable_kwargs)
           ^^^^^^^^^^^^^^^^^^^^^^^^^^^^^^^^^^^^^^^^^^^^^^^^^^^^^^^^^^^^
  File "/home/airflow/.local/lib/python3.12/site-packages/airflow/models/baseoperator.py", line 401, in wrapper
    return func(self, *args, **kwargs)
           ^^^^^^^^^^^^^^^^^^^^^^^^^^^
  File "/home/airflow/.local/lib/python3.12/site-packages/airflow/operators/python.py", line 235, in execute
    return_value = self.execute_callable()
                   ^^^^^^^^^^^^^^^^^^^^^^^
  File "/home/airflow/.local/lib/python3.12/site-packages/airflow/operators/python.py", line 252, in execute_callable
    return self.python_callable(*self.op_args, **self.op_kwargs)
           ^^^^^^^^^^^^^^^^^^^^^^^^^^^^^^^^^^^^^^^^^^^^^^^^^^^^^
  File "/opt/airflow/plugins/etl_scripts/load_to_postgres.py", line 92, in load_all_processed_data_to_postgres
    raise ValueError(f"Un ou plusieurs chargements en base de données ont échoué pour l'année {year}.")
ValueError: Un ou plusieurs chargements en base de données ont échoué pour l'année 2024.
[2025-06-03T18:58:07.701+0000] {taskinstance.py:1206} INFO - Marking task as FAILED. dag_id=f1_data_extraction_pipeline, task_id=load_data_to_postgres, run_id=manual__2025-06-03T18:57:56+00:00, execution_date=20250603T185756, start_date=20250603T185807, end_date=20250603T185807
[2025-06-03T18:58:07.706+0000] {standard_task_runner.py:110} ERROR - Failed to execute job 66 for task load_data_to_postgres (Un ou plusieurs chargements en base de données ont échoué pour l'année 2024.; 204)
[2025-06-03T18:58:07.720+0000] {local_task_job_runner.py:240} INFO - Task exited with return code 1
[2025-06-03T18:58:07.730+0000] {taskinstance.py:3503} INFO - 0 downstream tasks scheduled from follow-on schedule check
[2025-06-03T18:58:07.731+0000] {local_task_job_runner.py:222} INFO - ::endgroup::
