[2025-06-04T08:29:32.104+0000] {local_task_job_runner.py:120} INFO - ::group::Pre task execution logs
[2025-06-04T08:29:32.118+0000] {taskinstance.py:2076} INFO - Dependencies all met for dep_context=non-requeueable deps ti=<TaskInstance: f1_data_extraction_pipeline.fetch_all_round_details manual__2025-06-04T08:29:23+00:00 [queued]>
[2025-06-04T08:29:32.121+0000] {taskinstance.py:2076} INFO - Dependencies all met for dep_context=requeueable deps ti=<TaskInstance: f1_data_extraction_pipeline.fetch_all_round_details manual__2025-06-04T08:29:23+00:00 [queued]>
[2025-06-04T08:29:32.122+0000] {taskinstance.py:2306} INFO - Starting attempt 1 of 1
[2025-06-04T08:29:32.127+0000] {taskinstance.py:2330} INFO - Executing <Task(PythonOperator): fetch_all_round_details> on 2025-06-04 08:29:23+00:00
[2025-06-04T08:29:32.130+0000] {standard_task_runner.py:90} INFO - Running: ['***', 'tasks', 'run', 'f1_data_extraction_pipeline', 'fetch_all_round_details', 'manual__2025-06-04T08:29:23+00:00', '--job-id', '10', '--raw', '--subdir', 'DAGS_FOLDER/f1_pipeline.py', '--cfg-path', '/tmp/tmppv2wvhji']
[2025-06-04T08:29:32.133+0000] {standard_task_runner.py:91} INFO - Job 10: Subtask fetch_all_round_details
[2025-06-04T08:29:32.244+0000] {logging_mixin.py:188} WARNING - /home/***/.local/lib/python3.12/site-packages/***/task/task_runner/standard_task_runner.py:61 DeprecationWarning: This process (pid=605) is multi-threaded, use of fork() may lead to deadlocks in the child.
[2025-06-04T08:29:32.245+0000] {standard_task_runner.py:63} INFO - Started process 606 to run task
[2025-06-04T08:29:32.268+0000] {task_command.py:426} INFO - Running <TaskInstance: f1_data_extraction_pipeline.fetch_all_round_details manual__2025-06-04T08:29:23+00:00 [running]> on host 98906ef28ad4
[2025-06-04T08:29:32.309+0000] {taskinstance.py:2648} INFO - Exporting env vars: AIRFLOW_CTX_DAG_OWNER='***' AIRFLOW_CTX_DAG_ID='f1_data_extraction_pipeline' AIRFLOW_CTX_TASK_ID='fetch_all_round_details' AIRFLOW_CTX_EXECUTION_DATE='2025-06-04T08:29:23+00:00' AIRFLOW_CTX_TRY_NUMBER='1' AIRFLOW_CTX_DAG_RUN_ID='manual__2025-06-04T08:29:23+00:00'
[2025-06-04T08:29:32.309+0000] {taskinstance.py:430} INFO - ::endgroup::
[2025-06-04T08:29:32.314+0000] {logging_mixin.py:188} INFO - Chaîne XCom brute pour rounds_list: 'False'
[2025-06-04T08:29:32.315+0000] {logging_mixin.py:188} INFO - Erreur lors de l'analyse de la chaîne rounds_list ('False') depuis XCom. Erreur: La valeur XCom pour rounds_list n'est pas une liste après évaluation: False
[2025-06-04T08:29:32.315+0000] {taskinstance.py:441} INFO - ::group::Post task execution logs
[2025-06-04T08:29:32.315+0000] {taskinstance.py:2905} ERROR - Task failed with exception
Traceback (most recent call last):
  File "/opt/airflow/dags/f1_pipeline.py", line 32, in _fetch_all_rounds_callable
    raise ValueError(f"La valeur XCom pour rounds_list n'est pas une liste après évaluation: {parsed_value}")
ValueError: La valeur XCom pour rounds_list n'est pas une liste après évaluation: False

The above exception was the direct cause of the following exception:

Traceback (most recent call last):
  File "/home/airflow/.local/lib/python3.12/site-packages/airflow/models/taskinstance.py", line 465, in _execute_task
    result = _execute_callable(context=context, **execute_callable_kwargs)
             ^^^^^^^^^^^^^^^^^^^^^^^^^^^^^^^^^^^^^^^^^^^^^^^^^^^^^^^^^^^^^
  File "/home/airflow/.local/lib/python3.12/site-packages/airflow/models/taskinstance.py", line 432, in _execute_callable
    return execute_callable(context=context, **execute_callable_kwargs)
           ^^^^^^^^^^^^^^^^^^^^^^^^^^^^^^^^^^^^^^^^^^^^^^^^^^^^^^^^^^^^
  File "/home/airflow/.local/lib/python3.12/site-packages/airflow/models/baseoperator.py", line 401, in wrapper
    return func(self, *args, **kwargs)
           ^^^^^^^^^^^^^^^^^^^^^^^^^^^
  File "/home/airflow/.local/lib/python3.12/site-packages/airflow/operators/python.py", line 235, in execute
    return_value = self.execute_callable()
                   ^^^^^^^^^^^^^^^^^^^^^^^
  File "/home/airflow/.local/lib/python3.12/site-packages/airflow/operators/python.py", line 252, in execute_callable
    return self.python_callable(*self.op_args, **self.op_kwargs)
           ^^^^^^^^^^^^^^^^^^^^^^^^^^^^^^^^^^^^^^^^^^^^^^^^^^^^^
  File "/opt/airflow/dags/f1_pipeline.py", line 36, in _fetch_all_rounds_callable
    raise ValueError(f"Impossible de parser rounds_list depuis XCom: '{rounds_list_str}'") from e
ValueError: Impossible de parser rounds_list depuis XCom: 'False'
[2025-06-04T08:29:32.321+0000] {taskinstance.py:1206} INFO - Marking task as FAILED. dag_id=f1_data_extraction_pipeline, task_id=fetch_all_round_details, run_id=manual__2025-06-04T08:29:23+00:00, execution_date=20250604T082923, start_date=20250604T082932, end_date=20250604T082932
[2025-06-04T08:29:32.324+0000] {standard_task_runner.py:110} ERROR - Failed to execute job 10 for task fetch_all_round_details (Impossible de parser rounds_list depuis XCom: 'False'; 606)
[2025-06-04T08:29:32.350+0000] {local_task_job_runner.py:240} INFO - Task exited with return code 1
[2025-06-04T08:29:32.360+0000] {taskinstance.py:3503} INFO - 0 downstream tasks scheduled from follow-on schedule check
[2025-06-04T08:29:32.361+0000] {local_task_job_runner.py:222} INFO - ::endgroup::
