[2025-06-03T18:54:24.073+0000] {local_task_job_runner.py:120} INFO - ::group::Pre task execution logs
[2025-06-03T18:54:24.093+0000] {taskinstance.py:2076} INFO - Dependencies all met for dep_context=non-requeueable deps ti=<TaskInstance: f1_data_extraction_pipeline.load_data_to_postgres manual__2025-06-03T18:53:46+00:00 [queued]>
[2025-06-03T18:54:24.098+0000] {taskinstance.py:2076} INFO - Dependencies all met for dep_context=requeueable deps ti=<TaskInstance: f1_data_extraction_pipeline.load_data_to_postgres manual__2025-06-03T18:53:46+00:00 [queued]>
[2025-06-03T18:54:24.098+0000] {taskinstance.py:2306} INFO - Starting attempt 1 of 1
[2025-06-03T18:54:24.106+0000] {taskinstance.py:2330} INFO - Executing <Task(PythonOperator): load_data_to_postgres> on 2025-06-03 18:53:46+00:00
[2025-06-03T18:54:24.112+0000] {standard_task_runner.py:90} INFO - Running: ['***', 'tasks', 'run', 'f1_data_extraction_pipeline', 'load_data_to_postgres', 'manual__2025-06-03T18:53:46+00:00', '--job-id', '60', '--raw', '--subdir', 'DAGS_FOLDER/f1_pipeline.py', '--cfg-path', '/tmp/tmptkjw9z6a']
[2025-06-03T18:54:24.117+0000] {standard_task_runner.py:91} INFO - Job 60: Subtask load_data_to_postgres
[2025-06-03T18:54:24.247+0000] {logging_mixin.py:188} WARNING - /home/***/.local/lib/python3.12/site-packages/***/task/task_runner/standard_task_runner.py:61 DeprecationWarning: This process (pid=439) is multi-threaded, use of fork() may lead to deadlocks in the child.
[2025-06-03T18:54:24.248+0000] {standard_task_runner.py:63} INFO - Started process 440 to run task
[2025-06-03T18:54:24.269+0000] {task_command.py:426} INFO - Running <TaskInstance: f1_data_extraction_pipeline.load_data_to_postgres manual__2025-06-03T18:53:46+00:00 [running]> on host 272d0a595586
[2025-06-03T18:54:24.332+0000] {taskinstance.py:2648} INFO - Exporting env vars: AIRFLOW_CTX_DAG_OWNER='***' AIRFLOW_CTX_DAG_ID='f1_data_extraction_pipeline' AIRFLOW_CTX_TASK_ID='load_data_to_postgres' AIRFLOW_CTX_EXECUTION_DATE='2025-06-03T18:53:46+00:00' AIRFLOW_CTX_TRY_NUMBER='1' AIRFLOW_CTX_DAG_RUN_ID='manual__2025-06-03T18:53:46+00:00'
[2025-06-03T18:54:24.333+0000] {taskinstance.py:430} INFO - ::endgroup::
[2025-06-03T18:54:24.340+0000] {logging_mixin.py:188} INFO - Début du chargement en base de données pour l'année 2024.
[2025-06-03T18:54:24.341+0000] {logging_mixin.py:188} INFO - Fichier CSV non trouvé : /opt/***/data/processed/2024/circuits_info.csv. Chargement sauté pour la table circuits.
[2025-06-03T18:54:24.374+0000] {base.py:84} INFO - Using connection ID 'f1_postgres_db' for task execution.
[2025-06-03T18:54:24.412+0000] {logging_mixin.py:188} INFO - Données de /opt/***/data/processed/2024/drivers.csv chargées avec succès dans la table drivers.
[2025-06-03T18:54:24.420+0000] {base.py:84} INFO - Using connection ID 'f1_postgres_db' for task execution.
[2025-06-03T18:54:24.429+0000] {logging_mixin.py:188} INFO - Données de /opt/***/data/processed/2024/constructors.csv chargées avec succès dans la table constructors.
[2025-06-03T18:54:24.440+0000] {base.py:84} INFO - Using connection ID 'f1_postgres_db' for task execution.
[2025-06-03T18:54:24.440+0000] {logging_mixin.py:188} INFO - Exécution : DELETE FROM races WHERE year = 2024;
[2025-06-03T18:54:24.445+0000] {base.py:84} INFO - Using connection ID 'f1_postgres_db' for task execution.
[2025-06-03T18:54:24.449+0000] {sql.py:487} INFO - Running statement: DELETE FROM races WHERE year = 2024;, parameters: None
[2025-06-03T18:54:24.450+0000] {logging_mixin.py:188} INFO - Erreur lors du chargement de /opt/***/data/processed/2024/races_schedule.csv vers la table races:
[2025-06-03T18:54:24.451+0000] {logging_mixin.py:188} WARNING - Traceback (most recent call last):
[2025-06-03T18:54:24.451+0000] {logging_mixin.py:188} WARNING -   File "/opt/***/plugins/etl_scripts/load_to_postgres.py", line 45, in _load_single_csv_to_db
    pg_hook.run(delete_sql)
[2025-06-03T18:54:24.451+0000] {logging_mixin.py:188} WARNING -   File "/home/***/.local/lib/python3.12/site-packages/***/providers/common/sql/hooks/sql.py", line 435, in run
    self._run_command(cur, sql_statement, parameters)
[2025-06-03T18:54:24.452+0000] {logging_mixin.py:188} WARNING -   File "/home/***/.local/lib/python3.12/site-packages/***/providers/common/sql/hooks/sql.py", line 492, in _run_command
    cur.execute(sql_statement)
[2025-06-03T18:54:24.452+0000] {logging_mixin.py:188} WARNING - psycopg2.errors.UndefinedTable: relation "races" does not exist
LINE 1: DELETE FROM races WHERE year = 2024;
                    ^
[2025-06-03T18:54:24.452+0000] {logging_mixin.py:188} INFO - Échec du chargement pour races. Poursuite avec les autres tables si possible.
[2025-06-03T18:54:24.459+0000] {base.py:84} INFO - Using connection ID 'f1_postgres_db' for task execution.
[2025-06-03T18:54:24.460+0000] {logging_mixin.py:188} INFO - Exécution : DELETE FROM results WHERE race_id LIKE '2024_%';
[2025-06-03T18:54:24.464+0000] {base.py:84} INFO - Using connection ID 'f1_postgres_db' for task execution.
[2025-06-03T18:54:24.468+0000] {sql.py:487} INFO - Running statement: DELETE FROM results WHERE race_id LIKE '2024_%';, parameters: None
[2025-06-03T18:54:24.468+0000] {logging_mixin.py:188} INFO - Erreur lors du chargement de /opt/***/data/processed/2024/detailed_results.csv vers la table results:
[2025-06-03T18:54:24.468+0000] {logging_mixin.py:188} WARNING - Traceback (most recent call last):
[2025-06-03T18:54:24.469+0000] {logging_mixin.py:188} WARNING -   File "/opt/***/plugins/etl_scripts/load_to_postgres.py", line 49, in _load_single_csv_to_db
    pg_hook.run(delete_sql)
[2025-06-03T18:54:24.470+0000] {logging_mixin.py:188} WARNING -   File "/home/***/.local/lib/python3.12/site-packages/***/providers/common/sql/hooks/sql.py", line 435, in run
    self._run_command(cur, sql_statement, parameters)
[2025-06-03T18:54:24.470+0000] {logging_mixin.py:188} WARNING -   File "/home/***/.local/lib/python3.12/site-packages/***/providers/common/sql/hooks/sql.py", line 492, in _run_command
    cur.execute(sql_statement)
[2025-06-03T18:54:24.470+0000] {logging_mixin.py:188} WARNING - psycopg2.errors.UndefinedTable: relation "results" does not exist
LINE 1: DELETE FROM results WHERE race_id LIKE '2024_%';
                    ^
[2025-06-03T18:54:24.470+0000] {logging_mixin.py:188} INFO - Échec du chargement pour results. Poursuite avec les autres tables si possible.
[2025-06-03T18:54:24.471+0000] {taskinstance.py:441} INFO - ::group::Post task execution logs
[2025-06-03T18:54:24.471+0000] {taskinstance.py:2905} ERROR - Task failed with exception
Traceback (most recent call last):
  File "/home/airflow/.local/lib/python3.12/site-packages/airflow/models/taskinstance.py", line 465, in _execute_task
    result = _execute_callable(context=context, **execute_callable_kwargs)
             ^^^^^^^^^^^^^^^^^^^^^^^^^^^^^^^^^^^^^^^^^^^^^^^^^^^^^^^^^^^^^
  File "/home/airflow/.local/lib/python3.12/site-packages/airflow/models/taskinstance.py", line 432, in _execute_callable
    return execute_callable(context=context, **execute_callable_kwargs)
           ^^^^^^^^^^^^^^^^^^^^^^^^^^^^^^^^^^^^^^^^^^^^^^^^^^^^^^^^^^^^
  File "/home/airflow/.local/lib/python3.12/site-packages/airflow/models/baseoperator.py", line 401, in wrapper
    return func(self, *args, **kwargs)
           ^^^^^^^^^^^^^^^^^^^^^^^^^^^
  File "/home/airflow/.local/lib/python3.12/site-packages/airflow/operators/python.py", line 235, in execute
    return_value = self.execute_callable()
                   ^^^^^^^^^^^^^^^^^^^^^^^
  File "/home/airflow/.local/lib/python3.12/site-packages/airflow/operators/python.py", line 252, in execute_callable
    return self.python_callable(*self.op_args, **self.op_kwargs)
           ^^^^^^^^^^^^^^^^^^^^^^^^^^^^^^^^^^^^^^^^^^^^^^^^^^^^^
  File "/opt/airflow/plugins/etl_scripts/load_to_postgres.py", line 92, in load_all_processed_data_to_postgres
    raise ValueError(f"Un ou plusieurs chargements en base de données ont échoué pour l'année {year}.")
ValueError: Un ou plusieurs chargements en base de données ont échoué pour l'année 2024.
[2025-06-03T18:54:24.478+0000] {taskinstance.py:1206} INFO - Marking task as FAILED. dag_id=f1_data_extraction_pipeline, task_id=load_data_to_postgres, run_id=manual__2025-06-03T18:53:46+00:00, execution_date=20250603T185346, start_date=20250603T185424, end_date=20250603T185424
[2025-06-03T18:54:24.483+0000] {standard_task_runner.py:110} ERROR - Failed to execute job 60 for task load_data_to_postgres (Un ou plusieurs chargements en base de données ont échoué pour l'année 2024.; 440)
[2025-06-03T18:54:24.516+0000] {local_task_job_runner.py:240} INFO - Task exited with return code 1
[2025-06-03T18:54:24.525+0000] {taskinstance.py:3503} INFO - 0 downstream tasks scheduled from follow-on schedule check
[2025-06-03T18:54:24.526+0000] {local_task_job_runner.py:222} INFO - ::endgroup::
