[2025-06-04T08:30:31.415+0000] {local_task_job_runner.py:120} INFO - ::group::Pre task execution logs
[2025-06-04T08:30:31.430+0000] {taskinstance.py:2076} INFO - Dependencies all met for dep_context=non-requeueable deps ti=<TaskInstance: f1_data_extraction_pipeline.load_data_to_postgres manual__2025-06-04T08:29:53+00:00 [queued]>
[2025-06-04T08:30:31.433+0000] {taskinstance.py:2076} INFO - Dependencies all met for dep_context=requeueable deps ti=<TaskInstance: f1_data_extraction_pipeline.load_data_to_postgres manual__2025-06-04T08:29:53+00:00 [queued]>
[2025-06-04T08:30:31.434+0000] {taskinstance.py:2306} INFO - Starting attempt 1 of 1
[2025-06-04T08:30:31.439+0000] {taskinstance.py:2330} INFO - Executing <Task(PythonOperator): load_data_to_postgres> on 2025-06-04 08:29:53+00:00
[2025-06-04T08:30:31.443+0000] {standard_task_runner.py:90} INFO - Running: ['***', 'tasks', 'run', 'f1_data_extraction_pipeline', 'load_data_to_postgres', 'manual__2025-06-04T08:29:53+00:00', '--job-id', '15', '--raw', '--subdir', 'DAGS_FOLDER/f1_pipeline.py', '--cfg-path', '/tmp/tmpacprtpis']
[2025-06-04T08:30:31.447+0000] {standard_task_runner.py:91} INFO - Job 15: Subtask load_data_to_postgres
[2025-06-04T08:30:31.536+0000] {logging_mixin.py:188} WARNING - /home/***/.local/lib/python3.12/site-packages/***/task/task_runner/standard_task_runner.py:61 DeprecationWarning: This process (pid=651) is multi-threaded, use of fork() may lead to deadlocks in the child.
[2025-06-04T08:30:31.537+0000] {standard_task_runner.py:63} INFO - Started process 652 to run task
[2025-06-04T08:30:31.561+0000] {task_command.py:426} INFO - Running <TaskInstance: f1_data_extraction_pipeline.load_data_to_postgres manual__2025-06-04T08:29:53+00:00 [running]> on host 98906ef28ad4
[2025-06-04T08:30:31.597+0000] {taskinstance.py:2648} INFO - Exporting env vars: AIRFLOW_CTX_DAG_OWNER='***' AIRFLOW_CTX_DAG_ID='f1_data_extraction_pipeline' AIRFLOW_CTX_TASK_ID='load_data_to_postgres' AIRFLOW_CTX_EXECUTION_DATE='2025-06-04T08:29:53+00:00' AIRFLOW_CTX_TRY_NUMBER='1' AIRFLOW_CTX_DAG_RUN_ID='manual__2025-06-04T08:29:53+00:00'
[2025-06-04T08:30:31.597+0000] {taskinstance.py:430} INFO - ::endgroup::
[2025-06-04T08:30:31.602+0000] {logging_mixin.py:188} INFO - Début du chargement en base de données pour l'année 2023.
[2025-06-04T08:30:31.602+0000] {logging_mixin.py:188} INFO - Nettoyage préalable : DELETE FROM results WHERE race_id LIKE '2023_%';
[2025-06-04T08:30:31.612+0000] {base.py:84} INFO - Using connection ID 'f1_postgres_db' for task execution.
[2025-06-04T08:30:31.614+0000] {sql.py:487} INFO - Running statement: DELETE FROM results WHERE race_id LIKE '2023_%';, parameters: None
[2025-06-04T08:30:31.615+0000] {sql.py:496} INFO - Rows affected: 0
[2025-06-04T08:30:31.615+0000] {logging_mixin.py:188} INFO - Nettoyage préalable : DELETE FROM races WHERE year = 2023;
[2025-06-04T08:30:31.619+0000] {base.py:84} INFO - Using connection ID 'f1_postgres_db' for task execution.
[2025-06-04T08:30:31.621+0000] {sql.py:487} INFO - Running statement: DELETE FROM races WHERE year = 2023;, parameters: None
[2025-06-04T08:30:31.621+0000] {sql.py:496} INFO - Rows affected: 0
[2025-06-04T08:30:31.621+0000] {logging_mixin.py:188} INFO - 
--- Début du traitement pour circuits_info.csv vers table circuits ---
[2025-06-04T08:30:31.629+0000] {base.py:84} INFO - Using connection ID 'f1_postgres_db' for task execution.
[2025-06-04T08:30:31.640+0000] {logging_mixin.py:188} INFO - Erreur générique lors du chargement de /opt/***/data/processed/2023/circuits_info.csv vers la table circuits:
[2025-06-04T08:30:31.645+0000] {logging_mixin.py:188} WARNING - Traceback (most recent call last):
[2025-06-04T08:30:31.645+0000] {logging_mixin.py:188} WARNING -   File "/home/***/.local/lib/python3.12/site-packages/sqlalchemy/engine/base.py", line 1890, in _execute_context
    self.dialect.do_executemany(
[2025-06-04T08:30:31.645+0000] {logging_mixin.py:188} WARNING -   File "/home/***/.local/lib/python3.12/site-packages/sqlalchemy/dialects/postgresql/psycopg2.py", line 982, in do_executemany
    context._psycopg2_fetched_rows = xtras.execute_values(
                                     ^^^^^^^^^^^^^^^^^^^^^
[2025-06-04T08:30:31.645+0000] {logging_mixin.py:188} WARNING -   File "/home/***/.local/lib/python3.12/site-packages/psycopg2/extras.py", line 1299, in execute_values
    cur.execute(b''.join(parts))
[2025-06-04T08:30:31.646+0000] {logging_mixin.py:188} WARNING - psycopg2.errors.UniqueViolation: duplicate key value violates unique constraint "circuits_pkey"
DETAIL:  Key (circuit_id)=(bahrain) already exists.
[2025-06-04T08:30:31.646+0000] {logging_mixin.py:188} WARNING - 
The above exception was the direct cause of the following exception:
[2025-06-04T08:30:31.646+0000] {logging_mixin.py:188} WARNING - Traceback (most recent call last):
[2025-06-04T08:30:31.646+0000] {logging_mixin.py:188} WARNING -   File "/opt/***/plugins/etl_scripts/load_to_postgres.py", line 44, in _load_single_csv_to_db
    df.to_sql(name=table_name, con=engine, if_exists='append', index=False, schema='public')
[2025-06-04T08:30:31.646+0000] {logging_mixin.py:188} WARNING -   File "/home/***/.local/lib/python3.12/site-packages/pandas/util/_decorators.py", line 333, in wrapper
    return func(*args, **kwargs)
           ^^^^^^^^^^^^^^^^^^^^^
[2025-06-04T08:30:31.646+0000] {logging_mixin.py:188} WARNING -   File "/home/***/.local/lib/python3.12/site-packages/pandas/core/generic.py", line 3008, in to_sql
    return sql.to_sql(
           ^^^^^^^^^^^
[2025-06-04T08:30:31.646+0000] {logging_mixin.py:188} WARNING -   File "/home/***/.local/lib/python3.12/site-packages/pandas/io/sql.py", line 788, in to_sql
    return pandas_sql.to_sql(
           ^^^^^^^^^^^^^^^^^^
[2025-06-04T08:30:31.646+0000] {logging_mixin.py:188} WARNING -   File "/home/***/.local/lib/python3.12/site-packages/pandas/io/sql.py", line 1958, in to_sql
    total_inserted = sql_engine.insert_records(
                     ^^^^^^^^^^^^^^^^^^^^^^^^^^
[2025-06-04T08:30:31.646+0000] {logging_mixin.py:188} WARNING -   File "/home/***/.local/lib/python3.12/site-packages/pandas/io/sql.py", line 1507, in insert_records
    raise err
[2025-06-04T08:30:31.646+0000] {logging_mixin.py:188} WARNING -   File "/home/***/.local/lib/python3.12/site-packages/pandas/io/sql.py", line 1498, in insert_records
    return table.insert(chunksize=chunksize, method=method)
           ^^^^^^^^^^^^^^^^^^^^^^^^^^^^^^^^^^^^^^^^^^^^^^^^
[2025-06-04T08:30:31.646+0000] {logging_mixin.py:188} WARNING -   File "/home/***/.local/lib/python3.12/site-packages/pandas/io/sql.py", line 1059, in insert
    num_inserted = exec_insert(conn, keys, chunk_iter)
                   ^^^^^^^^^^^^^^^^^^^^^^^^^^^^^^^^^^^
[2025-06-04T08:30:31.646+0000] {logging_mixin.py:188} WARNING -   File "/home/***/.local/lib/python3.12/site-packages/pandas/io/sql.py", line 951, in _execute_insert
    result = conn.execute(self.table.insert(), data)
             ^^^^^^^^^^^^^^^^^^^^^^^^^^^^^^^^^^^^^^^
[2025-06-04T08:30:31.646+0000] {logging_mixin.py:188} WARNING -   File "/home/***/.local/lib/python3.12/site-packages/sqlalchemy/engine/base.py", line 1385, in execute
    return meth(self, multiparams, params, _EMPTY_EXECUTION_OPTS)
           ^^^^^^^^^^^^^^^^^^^^^^^^^^^^^^^^^^^^^^^^^^^^^^^^^^^^^^
[2025-06-04T08:30:31.647+0000] {logging_mixin.py:188} WARNING -   File "/home/***/.local/lib/python3.12/site-packages/sqlalchemy/sql/elements.py", line 334, in _execute_on_connection
    return connection._execute_clauseelement(
           ^^^^^^^^^^^^^^^^^^^^^^^^^^^^^^^^^^
[2025-06-04T08:30:31.647+0000] {logging_mixin.py:188} WARNING -   File "/home/***/.local/lib/python3.12/site-packages/sqlalchemy/engine/base.py", line 1577, in _execute_clauseelement
    ret = self._execute_context(
          ^^^^^^^^^^^^^^^^^^^^^^
[2025-06-04T08:30:31.647+0000] {logging_mixin.py:188} WARNING -   File "/home/***/.local/lib/python3.12/site-packages/sqlalchemy/engine/base.py", line 1953, in _execute_context
    self._handle_dbapi_exception(
[2025-06-04T08:30:31.647+0000] {logging_mixin.py:188} WARNING -   File "/home/***/.local/lib/python3.12/site-packages/sqlalchemy/engine/base.py", line 2134, in _handle_dbapi_exception
    util.raise_(
[2025-06-04T08:30:31.647+0000] {logging_mixin.py:188} WARNING -   File "/home/***/.local/lib/python3.12/site-packages/sqlalchemy/util/compat.py", line 211, in raise_
    raise exception
[2025-06-04T08:30:31.647+0000] {logging_mixin.py:188} WARNING -   File "/home/***/.local/lib/python3.12/site-packages/sqlalchemy/engine/base.py", line 1890, in _execute_context
    self.dialect.do_executemany(
[2025-06-04T08:30:31.647+0000] {logging_mixin.py:188} WARNING -   File "/home/***/.local/lib/python3.12/site-packages/sqlalchemy/dialects/postgresql/psycopg2.py", line 982, in do_executemany
    context._psycopg2_fetched_rows = xtras.execute_values(
                                     ^^^^^^^^^^^^^^^^^^^^^
[2025-06-04T08:30:31.647+0000] {logging_mixin.py:188} WARNING -   File "/home/***/.local/lib/python3.12/site-packages/psycopg2/extras.py", line 1299, in execute_values
    cur.execute(b''.join(parts))
[2025-06-04T08:30:31.647+0000] {logging_mixin.py:188} WARNING - sqlalchemy.exc.IntegrityError: (psycopg2.errors.UniqueViolation) duplicate key value violates unique constraint "circuits_pkey"
DETAIL:  Key (circuit_id)=(bahrain) already exists.

[SQL: INSERT INTO public.circuits (circuit_id, circuit_name, locality, country) VALUES (%(circuit_id)s, %(circuit_name)s, %(locality)s, %(country)s)]
[parameters: ({'circuit_id': 'bahrain', 'circuit_name': 'Bahrain International Circuit', 'locality': 'Sakhir', 'country': 'Bahrain'}, {'circuit_id': 'jeddah', 'circuit_name': 'Jeddah Corniche Circuit', 'locality': 'Jeddah', 'country': 'Saudi Arabia'}, {'circuit_id': 'albert_park', 'circuit_name': 'Albert Park Grand Prix Circuit', 'locality': 'Melbourne', 'country': 'Australia'}, {'circuit_id': 'baku', 'circuit_name': 'Baku City Circuit', 'locality': 'Baku', 'country': 'Azerbaijan'}, {'circuit_id': 'miami', 'circuit_name': 'Miami International Autodrome', 'locality': 'Miami', 'country': 'USA'}, {'circuit_id': 'monaco', 'circuit_name': 'Circuit de Monaco', 'locality': 'Monte-Carlo', 'country': 'Monaco'}, {'circuit_id': 'catalunya', 'circuit_name': 'Circuit de Barcelona-Catalunya', 'locality': 'Montmeló', 'country': 'Spain'}, {'circuit_id': 'villeneuve', 'circuit_name': 'Circuit Gilles Villeneuve', 'locality': 'Montreal', 'country': 'Canada'}  ... displaying 10 of 22 total bound parameter sets ...  {'circuit_id': 'vegas', 'circuit_name': 'Las Vegas Strip Street Circuit', 'locality': 'Las Vegas', 'country': 'United States'}, {'circuit_id': 'yas_marina', 'circuit_name': 'Yas Marina Circuit', 'locality': 'Abu Dhabi', 'country': 'UAE'})]
(Background on this error at: https://sqlalche.me/e/14/gkpj)
[2025-06-04T08:30:31.647+0000] {logging_mixin.py:188} INFO - --- Résultat pour circuits_info.csv: ÉCHEC ---
[2025-06-04T08:30:31.647+0000] {logging_mixin.py:188} INFO - 
--- Début du traitement pour drivers.csv vers table drivers ---
[2025-06-04T08:30:31.652+0000] {base.py:84} INFO - Using connection ID 'f1_postgres_db' for task execution.
[2025-06-04T08:30:31.656+0000] {logging_mixin.py:188} INFO - Erreur générique lors du chargement de /opt/***/data/processed/2023/drivers.csv vers la table drivers:
[2025-06-04T08:30:31.658+0000] {logging_mixin.py:188} WARNING - Traceback (most recent call last):
[2025-06-04T08:30:31.658+0000] {logging_mixin.py:188} WARNING -   File "/home/***/.local/lib/python3.12/site-packages/sqlalchemy/engine/base.py", line 1890, in _execute_context
    self.dialect.do_executemany(
[2025-06-04T08:30:31.658+0000] {logging_mixin.py:188} WARNING -   File "/home/***/.local/lib/python3.12/site-packages/sqlalchemy/dialects/postgresql/psycopg2.py", line 982, in do_executemany
    context._psycopg2_fetched_rows = xtras.execute_values(
                                     ^^^^^^^^^^^^^^^^^^^^^
[2025-06-04T08:30:31.658+0000] {logging_mixin.py:188} WARNING -   File "/home/***/.local/lib/python3.12/site-packages/psycopg2/extras.py", line 1299, in execute_values
    cur.execute(b''.join(parts))
[2025-06-04T08:30:31.658+0000] {logging_mixin.py:188} WARNING - psycopg2.errors.UniqueViolation: duplicate key value violates unique constraint "drivers_pkey"
DETAIL:  Key (driver_id)=(max_verstappen) already exists.
[2025-06-04T08:30:31.658+0000] {logging_mixin.py:188} WARNING - 
The above exception was the direct cause of the following exception:
[2025-06-04T08:30:31.658+0000] {logging_mixin.py:188} WARNING - Traceback (most recent call last):
[2025-06-04T08:30:31.658+0000] {logging_mixin.py:188} WARNING -   File "/opt/***/plugins/etl_scripts/load_to_postgres.py", line 44, in _load_single_csv_to_db
    df.to_sql(name=table_name, con=engine, if_exists='append', index=False, schema='public')
[2025-06-04T08:30:31.658+0000] {logging_mixin.py:188} WARNING -   File "/home/***/.local/lib/python3.12/site-packages/pandas/util/_decorators.py", line 333, in wrapper
    return func(*args, **kwargs)
           ^^^^^^^^^^^^^^^^^^^^^
[2025-06-04T08:30:31.659+0000] {logging_mixin.py:188} WARNING -   File "/home/***/.local/lib/python3.12/site-packages/pandas/core/generic.py", line 3008, in to_sql
    return sql.to_sql(
           ^^^^^^^^^^^
[2025-06-04T08:30:31.659+0000] {logging_mixin.py:188} WARNING -   File "/home/***/.local/lib/python3.12/site-packages/pandas/io/sql.py", line 788, in to_sql
    return pandas_sql.to_sql(
           ^^^^^^^^^^^^^^^^^^
[2025-06-04T08:30:31.659+0000] {logging_mixin.py:188} WARNING -   File "/home/***/.local/lib/python3.12/site-packages/pandas/io/sql.py", line 1958, in to_sql
    total_inserted = sql_engine.insert_records(
                     ^^^^^^^^^^^^^^^^^^^^^^^^^^
[2025-06-04T08:30:31.659+0000] {logging_mixin.py:188} WARNING -   File "/home/***/.local/lib/python3.12/site-packages/pandas/io/sql.py", line 1507, in insert_records
    raise err
[2025-06-04T08:30:31.659+0000] {logging_mixin.py:188} WARNING -   File "/home/***/.local/lib/python3.12/site-packages/pandas/io/sql.py", line 1498, in insert_records
    return table.insert(chunksize=chunksize, method=method)
           ^^^^^^^^^^^^^^^^^^^^^^^^^^^^^^^^^^^^^^^^^^^^^^^^
[2025-06-04T08:30:31.659+0000] {logging_mixin.py:188} WARNING -   File "/home/***/.local/lib/python3.12/site-packages/pandas/io/sql.py", line 1059, in insert
    num_inserted = exec_insert(conn, keys, chunk_iter)
                   ^^^^^^^^^^^^^^^^^^^^^^^^^^^^^^^^^^^
[2025-06-04T08:30:31.659+0000] {logging_mixin.py:188} WARNING -   File "/home/***/.local/lib/python3.12/site-packages/pandas/io/sql.py", line 951, in _execute_insert
    result = conn.execute(self.table.insert(), data)
             ^^^^^^^^^^^^^^^^^^^^^^^^^^^^^^^^^^^^^^^
[2025-06-04T08:30:31.659+0000] {logging_mixin.py:188} WARNING -   File "/home/***/.local/lib/python3.12/site-packages/sqlalchemy/engine/base.py", line 1385, in execute
    return meth(self, multiparams, params, _EMPTY_EXECUTION_OPTS)
           ^^^^^^^^^^^^^^^^^^^^^^^^^^^^^^^^^^^^^^^^^^^^^^^^^^^^^^
[2025-06-04T08:30:31.659+0000] {logging_mixin.py:188} WARNING -   File "/home/***/.local/lib/python3.12/site-packages/sqlalchemy/sql/elements.py", line 334, in _execute_on_connection
    return connection._execute_clauseelement(
           ^^^^^^^^^^^^^^^^^^^^^^^^^^^^^^^^^^
[2025-06-04T08:30:31.659+0000] {logging_mixin.py:188} WARNING -   File "/home/***/.local/lib/python3.12/site-packages/sqlalchemy/engine/base.py", line 1577, in _execute_clauseelement
    ret = self._execute_context(
          ^^^^^^^^^^^^^^^^^^^^^^
[2025-06-04T08:30:31.659+0000] {logging_mixin.py:188} WARNING -   File "/home/***/.local/lib/python3.12/site-packages/sqlalchemy/engine/base.py", line 1953, in _execute_context
    self._handle_dbapi_exception(
[2025-06-04T08:30:31.659+0000] {logging_mixin.py:188} WARNING -   File "/home/***/.local/lib/python3.12/site-packages/sqlalchemy/engine/base.py", line 2134, in _handle_dbapi_exception
    util.raise_(
[2025-06-04T08:30:31.659+0000] {logging_mixin.py:188} WARNING -   File "/home/***/.local/lib/python3.12/site-packages/sqlalchemy/util/compat.py", line 211, in raise_
    raise exception
[2025-06-04T08:30:31.659+0000] {logging_mixin.py:188} WARNING -   File "/home/***/.local/lib/python3.12/site-packages/sqlalchemy/engine/base.py", line 1890, in _execute_context
    self.dialect.do_executemany(
[2025-06-04T08:30:31.659+0000] {logging_mixin.py:188} WARNING -   File "/home/***/.local/lib/python3.12/site-packages/sqlalchemy/dialects/postgresql/psycopg2.py", line 982, in do_executemany
    context._psycopg2_fetched_rows = xtras.execute_values(
                                     ^^^^^^^^^^^^^^^^^^^^^
[2025-06-04T08:30:31.659+0000] {logging_mixin.py:188} WARNING -   File "/home/***/.local/lib/python3.12/site-packages/psycopg2/extras.py", line 1299, in execute_values
    cur.execute(b''.join(parts))
[2025-06-04T08:30:31.660+0000] {logging_mixin.py:188} WARNING - sqlalchemy.exc.IntegrityError: (psycopg2.errors.UniqueViolation) duplicate key value violates unique constraint "drivers_pkey"
DETAIL:  Key (driver_id)=(max_verstappen) already exists.

[SQL: INSERT INTO public.drivers (driver_id, permanent_number, code, given_name, family_name, date_of_birth, nationality) VALUES (%(driver_id)s, %(permanent_number)s, %(code)s, %(given_name)s, %(family_name)s, %(date_of_birth)s, %(nationality)s)]
[parameters: ({'driver_id': 'max_verstappen', 'permanent_number': 33, 'code': 'VER', 'given_name': 'Max', 'family_name': 'Verstappen', 'date_of_birth': '1997-09-30', 'nationality': 'Dutch'}, {'driver_id': 'perez', 'permanent_number': 11, 'code': 'PER', 'given_name': 'Sergio', 'family_name': 'Pérez', 'date_of_birth': '1990-01-26', 'nationality': 'Mexican'}, {'driver_id': 'alonso', 'permanent_number': 14, 'code': 'ALO', 'given_name': 'Fernando', 'family_name': 'Alonso', 'date_of_birth': '1981-07-29', 'nationality': 'Spanish'}, {'driver_id': 'sainz', 'permanent_number': 55, 'code': 'SAI', 'given_name': 'Carlos', 'family_name': 'Sainz', 'date_of_birth': '1994-09-01', 'nationality': 'Spanish'}, {'driver_id': 'hamilton', 'permanent_number': 44, 'code': 'HAM', 'given_name': 'Lewis', 'family_name': 'Hamilton', 'date_of_birth': '1985-01-07', 'nationality': 'British'}, {'driver_id': 'stroll', 'permanent_number': 18, 'code': 'STR', 'given_name': 'Lance', 'family_name': 'Stroll', 'date_of_birth': '1998-10-29', 'nationality': 'Canadian'}, {'driver_id': 'russell', 'permanent_number': 63, 'code': 'RUS', 'given_name': 'George', 'family_name': 'Russell', 'date_of_birth': '1998-02-15', 'nationality': 'British'}, {'driver_id': 'bottas', 'permanent_number': 77, 'code': 'BOT', 'given_name': 'Valtteri', 'family_name': 'Bottas', 'date_of_birth': '1989-08-28', 'nationality': 'Finnish'}  ... displaying 10 of 20 total bound parameter sets ...  {'driver_id': 'leclerc', 'permanent_number': 16, 'code': 'LEC', 'given_name': 'Charles', 'family_name': 'Leclerc', 'date_of_birth': '1997-10-16', 'nationality': 'Monegasque'}, {'driver_id': 'piastri', 'permanent_number': 81, 'code': 'PIA', 'given_name': 'Oscar', 'family_name': 'Piastri', 'date_of_birth': '2001-04-06', 'nationality': 'Australian'})]
(Background on this error at: https://sqlalche.me/e/14/gkpj)
[2025-06-04T08:30:31.660+0000] {logging_mixin.py:188} INFO - --- Résultat pour drivers.csv: ÉCHEC ---
[2025-06-04T08:30:31.660+0000] {logging_mixin.py:188} INFO - 
--- Début du traitement pour constructors.csv vers table constructors ---
[2025-06-04T08:30:31.664+0000] {base.py:84} INFO - Using connection ID 'f1_postgres_db' for task execution.
[2025-06-04T08:30:31.668+0000] {logging_mixin.py:188} INFO - Erreur générique lors du chargement de /opt/***/data/processed/2023/constructors.csv vers la table constructors:
[2025-06-04T08:30:31.669+0000] {logging_mixin.py:188} WARNING - Traceback (most recent call last):
[2025-06-04T08:30:31.669+0000] {logging_mixin.py:188} WARNING -   File "/home/***/.local/lib/python3.12/site-packages/sqlalchemy/engine/base.py", line 1890, in _execute_context
    self.dialect.do_executemany(
[2025-06-04T08:30:31.669+0000] {logging_mixin.py:188} WARNING -   File "/home/***/.local/lib/python3.12/site-packages/sqlalchemy/dialects/postgresql/psycopg2.py", line 982, in do_executemany
    context._psycopg2_fetched_rows = xtras.execute_values(
                                     ^^^^^^^^^^^^^^^^^^^^^
[2025-06-04T08:30:31.670+0000] {logging_mixin.py:188} WARNING -   File "/home/***/.local/lib/python3.12/site-packages/psycopg2/extras.py", line 1299, in execute_values
    cur.execute(b''.join(parts))
[2025-06-04T08:30:31.670+0000] {logging_mixin.py:188} WARNING - psycopg2.errors.UniqueViolation: duplicate key value violates unique constraint "constructors_pkey"
DETAIL:  Key (constructor_id)=(red_bull) already exists.
[2025-06-04T08:30:31.670+0000] {logging_mixin.py:188} WARNING - 
The above exception was the direct cause of the following exception:
[2025-06-04T08:30:31.670+0000] {logging_mixin.py:188} WARNING - Traceback (most recent call last):
[2025-06-04T08:30:31.670+0000] {logging_mixin.py:188} WARNING -   File "/opt/***/plugins/etl_scripts/load_to_postgres.py", line 44, in _load_single_csv_to_db
    df.to_sql(name=table_name, con=engine, if_exists='append', index=False, schema='public')
[2025-06-04T08:30:31.670+0000] {logging_mixin.py:188} WARNING -   File "/home/***/.local/lib/python3.12/site-packages/pandas/util/_decorators.py", line 333, in wrapper
    return func(*args, **kwargs)
           ^^^^^^^^^^^^^^^^^^^^^
[2025-06-04T08:30:31.670+0000] {logging_mixin.py:188} WARNING -   File "/home/***/.local/lib/python3.12/site-packages/pandas/core/generic.py", line 3008, in to_sql
    return sql.to_sql(
           ^^^^^^^^^^^
[2025-06-04T08:30:31.670+0000] {logging_mixin.py:188} WARNING -   File "/home/***/.local/lib/python3.12/site-packages/pandas/io/sql.py", line 788, in to_sql
    return pandas_sql.to_sql(
           ^^^^^^^^^^^^^^^^^^
[2025-06-04T08:30:31.670+0000] {logging_mixin.py:188} WARNING -   File "/home/***/.local/lib/python3.12/site-packages/pandas/io/sql.py", line 1958, in to_sql
    total_inserted = sql_engine.insert_records(
                     ^^^^^^^^^^^^^^^^^^^^^^^^^^
[2025-06-04T08:30:31.670+0000] {logging_mixin.py:188} WARNING -   File "/home/***/.local/lib/python3.12/site-packages/pandas/io/sql.py", line 1507, in insert_records
    raise err
[2025-06-04T08:30:31.670+0000] {logging_mixin.py:188} WARNING -   File "/home/***/.local/lib/python3.12/site-packages/pandas/io/sql.py", line 1498, in insert_records
    return table.insert(chunksize=chunksize, method=method)
           ^^^^^^^^^^^^^^^^^^^^^^^^^^^^^^^^^^^^^^^^^^^^^^^^
[2025-06-04T08:30:31.670+0000] {logging_mixin.py:188} WARNING -   File "/home/***/.local/lib/python3.12/site-packages/pandas/io/sql.py", line 1059, in insert
    num_inserted = exec_insert(conn, keys, chunk_iter)
                   ^^^^^^^^^^^^^^^^^^^^^^^^^^^^^^^^^^^
[2025-06-04T08:30:31.671+0000] {logging_mixin.py:188} WARNING -   File "/home/***/.local/lib/python3.12/site-packages/pandas/io/sql.py", line 951, in _execute_insert
    result = conn.execute(self.table.insert(), data)
             ^^^^^^^^^^^^^^^^^^^^^^^^^^^^^^^^^^^^^^^
[2025-06-04T08:30:31.671+0000] {logging_mixin.py:188} WARNING -   File "/home/***/.local/lib/python3.12/site-packages/sqlalchemy/engine/base.py", line 1385, in execute
    return meth(self, multiparams, params, _EMPTY_EXECUTION_OPTS)
           ^^^^^^^^^^^^^^^^^^^^^^^^^^^^^^^^^^^^^^^^^^^^^^^^^^^^^^
[2025-06-04T08:30:31.671+0000] {logging_mixin.py:188} WARNING -   File "/home/***/.local/lib/python3.12/site-packages/sqlalchemy/sql/elements.py", line 334, in _execute_on_connection
    return connection._execute_clauseelement(
           ^^^^^^^^^^^^^^^^^^^^^^^^^^^^^^^^^^
[2025-06-04T08:30:31.671+0000] {logging_mixin.py:188} WARNING -   File "/home/***/.local/lib/python3.12/site-packages/sqlalchemy/engine/base.py", line 1577, in _execute_clauseelement
    ret = self._execute_context(
          ^^^^^^^^^^^^^^^^^^^^^^
[2025-06-04T08:30:31.671+0000] {logging_mixin.py:188} WARNING -   File "/home/***/.local/lib/python3.12/site-packages/sqlalchemy/engine/base.py", line 1953, in _execute_context
    self._handle_dbapi_exception(
[2025-06-04T08:30:31.671+0000] {logging_mixin.py:188} WARNING -   File "/home/***/.local/lib/python3.12/site-packages/sqlalchemy/engine/base.py", line 2134, in _handle_dbapi_exception
    util.raise_(
[2025-06-04T08:30:31.671+0000] {logging_mixin.py:188} WARNING -   File "/home/***/.local/lib/python3.12/site-packages/sqlalchemy/util/compat.py", line 211, in raise_
    raise exception
[2025-06-04T08:30:31.671+0000] {logging_mixin.py:188} WARNING -   File "/home/***/.local/lib/python3.12/site-packages/sqlalchemy/engine/base.py", line 1890, in _execute_context
    self.dialect.do_executemany(
[2025-06-04T08:30:31.671+0000] {logging_mixin.py:188} WARNING -   File "/home/***/.local/lib/python3.12/site-packages/sqlalchemy/dialects/postgresql/psycopg2.py", line 982, in do_executemany
    context._psycopg2_fetched_rows = xtras.execute_values(
                                     ^^^^^^^^^^^^^^^^^^^^^
[2025-06-04T08:30:31.671+0000] {logging_mixin.py:188} WARNING -   File "/home/***/.local/lib/python3.12/site-packages/psycopg2/extras.py", line 1299, in execute_values
    cur.execute(b''.join(parts))
[2025-06-04T08:30:31.671+0000] {logging_mixin.py:188} WARNING - sqlalchemy.exc.IntegrityError: (psycopg2.errors.UniqueViolation) duplicate key value violates unique constraint "constructors_pkey"
DETAIL:  Key (constructor_id)=(red_bull) already exists.

[SQL: INSERT INTO public.constructors (constructor_id, name, nationality) VALUES (%(constructor_id)s, %(name)s, %(nationality)s)]
[parameters: ({'constructor_id': 'red_bull', 'name': 'Red Bull', 'nationality': 'Austrian'}, {'constructor_id': 'aston_martin', 'name': 'Aston Martin', 'nationality': 'British'}, {'constructor_id': 'ferrari', 'name': 'Ferrari', 'nationality': 'Italian'}, {'constructor_id': 'mercedes', 'name': 'Mercedes', 'nationality': 'German'}, {'constructor_id': 'alfa', 'name': 'Alfa Romeo', 'nationality': 'Swiss'}, {'constructor_id': 'alpine', 'name': 'Alpine F1 Team', 'nationality': 'French'}, {'constructor_id': 'williams', 'name': 'Williams', 'nationality': 'British'}, {'constructor_id': 'alphatauri', 'name': 'AlphaTauri', 'nationality': 'Italian'}, {'constructor_id': 'haas', 'name': 'Haas F1 Team', 'nationality': 'American'}, {'constructor_id': 'mclaren', 'name': 'McLaren', 'nationality': 'British'})]
(Background on this error at: https://sqlalche.me/e/14/gkpj)
[2025-06-04T08:30:31.671+0000] {logging_mixin.py:188} INFO - --- Résultat pour constructors.csv: ÉCHEC ---
[2025-06-04T08:30:31.671+0000] {logging_mixin.py:188} INFO - 
--- Début du traitement pour races_schedule.csv vers table races ---
[2025-06-04T08:30:31.675+0000] {base.py:84} INFO - Using connection ID 'f1_postgres_db' for task execution.
[2025-06-04T08:30:31.682+0000] {logging_mixin.py:188} INFO - Données de /opt/***/data/processed/2023/races_schedule.csv chargées avec succès dans la table races.
[2025-06-04T08:30:31.682+0000] {logging_mixin.py:188} INFO - --- Résultat pour races_schedule.csv: Succès ---
[2025-06-04T08:30:31.682+0000] {logging_mixin.py:188} INFO - 
--- Début du traitement pour detailed_results.csv vers table results ---
[2025-06-04T08:30:31.686+0000] {base.py:84} INFO - Using connection ID 'f1_postgres_db' for task execution.
[2025-06-04T08:30:31.698+0000] {logging_mixin.py:188} INFO - Erreur générique lors du chargement de /opt/***/data/processed/2023/detailed_results.csv vers la table results:
[2025-06-04T08:30:31.699+0000] {logging_mixin.py:188} WARNING - Traceback (most recent call last):
[2025-06-04T08:30:31.699+0000] {logging_mixin.py:188} WARNING -   File "/home/***/.local/lib/python3.12/site-packages/sqlalchemy/engine/base.py", line 1890, in _execute_context
    self.dialect.do_executemany(
[2025-06-04T08:30:31.700+0000] {logging_mixin.py:188} WARNING -   File "/home/***/.local/lib/python3.12/site-packages/sqlalchemy/dialects/postgresql/psycopg2.py", line 982, in do_executemany
    context._psycopg2_fetched_rows = xtras.execute_values(
                                     ^^^^^^^^^^^^^^^^^^^^^
[2025-06-04T08:30:31.700+0000] {logging_mixin.py:188} WARNING -   File "/home/***/.local/lib/python3.12/site-packages/psycopg2/extras.py", line 1299, in execute_values
    cur.execute(b''.join(parts))
[2025-06-04T08:30:31.700+0000] {logging_mixin.py:188} WARNING - psycopg2.errors.ForeignKeyViolation: insert or update on table "results" violates foreign key constraint "results_constructor_id_fkey"
DETAIL:  Key (constructor_id)=(alfa) is not present in table "constructors".
[2025-06-04T08:30:31.700+0000] {logging_mixin.py:188} WARNING - 
The above exception was the direct cause of the following exception:
[2025-06-04T08:30:31.700+0000] {logging_mixin.py:188} WARNING - Traceback (most recent call last):
[2025-06-04T08:30:31.700+0000] {logging_mixin.py:188} WARNING -   File "/opt/***/plugins/etl_scripts/load_to_postgres.py", line 44, in _load_single_csv_to_db
    df.to_sql(name=table_name, con=engine, if_exists='append', index=False, schema='public')
[2025-06-04T08:30:31.700+0000] {logging_mixin.py:188} WARNING -   File "/home/***/.local/lib/python3.12/site-packages/pandas/util/_decorators.py", line 333, in wrapper
    return func(*args, **kwargs)
           ^^^^^^^^^^^^^^^^^^^^^
[2025-06-04T08:30:31.700+0000] {logging_mixin.py:188} WARNING -   File "/home/***/.local/lib/python3.12/site-packages/pandas/core/generic.py", line 3008, in to_sql
    return sql.to_sql(
           ^^^^^^^^^^^
[2025-06-04T08:30:31.700+0000] {logging_mixin.py:188} WARNING -   File "/home/***/.local/lib/python3.12/site-packages/pandas/io/sql.py", line 788, in to_sql
    return pandas_sql.to_sql(
           ^^^^^^^^^^^^^^^^^^
[2025-06-04T08:30:31.700+0000] {logging_mixin.py:188} WARNING -   File "/home/***/.local/lib/python3.12/site-packages/pandas/io/sql.py", line 1958, in to_sql
    total_inserted = sql_engine.insert_records(
                     ^^^^^^^^^^^^^^^^^^^^^^^^^^
[2025-06-04T08:30:31.700+0000] {logging_mixin.py:188} WARNING -   File "/home/***/.local/lib/python3.12/site-packages/pandas/io/sql.py", line 1507, in insert_records
    raise err
[2025-06-04T08:30:31.701+0000] {logging_mixin.py:188} WARNING -   File "/home/***/.local/lib/python3.12/site-packages/pandas/io/sql.py", line 1498, in insert_records
    return table.insert(chunksize=chunksize, method=method)
           ^^^^^^^^^^^^^^^^^^^^^^^^^^^^^^^^^^^^^^^^^^^^^^^^
[2025-06-04T08:30:31.701+0000] {logging_mixin.py:188} WARNING -   File "/home/***/.local/lib/python3.12/site-packages/pandas/io/sql.py", line 1059, in insert
    num_inserted = exec_insert(conn, keys, chunk_iter)
                   ^^^^^^^^^^^^^^^^^^^^^^^^^^^^^^^^^^^
[2025-06-04T08:30:31.701+0000] {logging_mixin.py:188} WARNING -   File "/home/***/.local/lib/python3.12/site-packages/pandas/io/sql.py", line 951, in _execute_insert
    result = conn.execute(self.table.insert(), data)
             ^^^^^^^^^^^^^^^^^^^^^^^^^^^^^^^^^^^^^^^
[2025-06-04T08:30:31.701+0000] {logging_mixin.py:188} WARNING -   File "/home/***/.local/lib/python3.12/site-packages/sqlalchemy/engine/base.py", line 1385, in execute
    return meth(self, multiparams, params, _EMPTY_EXECUTION_OPTS)
           ^^^^^^^^^^^^^^^^^^^^^^^^^^^^^^^^^^^^^^^^^^^^^^^^^^^^^^
[2025-06-04T08:30:31.701+0000] {logging_mixin.py:188} WARNING -   File "/home/***/.local/lib/python3.12/site-packages/sqlalchemy/sql/elements.py", line 334, in _execute_on_connection
    return connection._execute_clauseelement(
           ^^^^^^^^^^^^^^^^^^^^^^^^^^^^^^^^^^
[2025-06-04T08:30:31.701+0000] {logging_mixin.py:188} WARNING -   File "/home/***/.local/lib/python3.12/site-packages/sqlalchemy/engine/base.py", line 1577, in _execute_clauseelement
    ret = self._execute_context(
          ^^^^^^^^^^^^^^^^^^^^^^
[2025-06-04T08:30:31.701+0000] {logging_mixin.py:188} WARNING -   File "/home/***/.local/lib/python3.12/site-packages/sqlalchemy/engine/base.py", line 1953, in _execute_context
    self._handle_dbapi_exception(
[2025-06-04T08:30:31.701+0000] {logging_mixin.py:188} WARNING -   File "/home/***/.local/lib/python3.12/site-packages/sqlalchemy/engine/base.py", line 2134, in _handle_dbapi_exception
    util.raise_(
[2025-06-04T08:30:31.701+0000] {logging_mixin.py:188} WARNING -   File "/home/***/.local/lib/python3.12/site-packages/sqlalchemy/util/compat.py", line 211, in raise_
    raise exception
[2025-06-04T08:30:31.701+0000] {logging_mixin.py:188} WARNING -   File "/home/***/.local/lib/python3.12/site-packages/sqlalchemy/engine/base.py", line 1890, in _execute_context
    self.dialect.do_executemany(
[2025-06-04T08:30:31.701+0000] {logging_mixin.py:188} WARNING -   File "/home/***/.local/lib/python3.12/site-packages/sqlalchemy/dialects/postgresql/psycopg2.py", line 982, in do_executemany
    context._psycopg2_fetched_rows = xtras.execute_values(
                                     ^^^^^^^^^^^^^^^^^^^^^
[2025-06-04T08:30:31.701+0000] {logging_mixin.py:188} WARNING -   File "/home/***/.local/lib/python3.12/site-packages/psycopg2/extras.py", line 1299, in execute_values
    cur.execute(b''.join(parts))
[2025-06-04T08:30:31.701+0000] {logging_mixin.py:188} WARNING - sqlalchemy.exc.IntegrityError: (psycopg2.errors.ForeignKeyViolation) insert or update on table "results" violates foreign key constraint "results_constructor_id_fkey"
DETAIL:  Key (constructor_id)=(alfa) is not present in table "constructors".

[SQL: INSERT INTO public.results (race_id, driver_id, constructor_id, car_number, grid_position, final_position, position_text, points, laps_completed, status, time_millis, time_text) VALUES (%(race_id)s, %(driver_id)s, %(constructor_id)s, %(car_number)s, %(grid_position)s, %(final_position)s, %(position_text)s, %(points)s, %(laps_completed)s, %(status)s, %(time_millis)s, %(time_text)s)]
[parameters: ({'race_id': '2023_1', 'driver_id': 'max_verstappen', 'constructor_id': 'red_bull', 'car_number': 1, 'grid_position': 1, 'final_position': 1, 'position_text': '1', 'points': 25.0, 'laps_completed': 57, 'status': 'Finished', 'time_millis': 5636736.0, 'time_text': '1:33:56.736'}, {'race_id': '2023_1', 'driver_id': 'perez', 'constructor_id': 'red_bull', 'car_number': 11, 'grid_position': 2, 'final_position': 2, 'position_text': '2', 'points': 18.0, 'laps_completed': 57, 'status': 'Finished', 'time_millis': 5648723.0, 'time_text': '+11.987'}, {'race_id': '2023_1', 'driver_id': 'alonso', 'constructor_id': 'aston_martin', 'car_number': 14, 'grid_position': 5, 'final_position': 3, 'position_text': '3', 'points': 15.0, 'laps_completed': 57, 'status': 'Finished', 'time_millis': 5675373.0, 'time_text': '+38.637'}, {'race_id': '2023_1', 'driver_id': 'sainz', 'constructor_id': 'ferrari', 'car_number': 55, 'grid_position': 4, 'final_position': 4, 'position_text': '4', 'points': 12.0, 'laps_completed': 57, 'status': 'Finished', 'time_millis': 5684788.0, 'time_text': '+48.052'}, {'race_id': '2023_1', 'driver_id': 'hamilton', 'constructor_id': 'mercedes', 'car_number': 44, 'grid_position': 7, 'final_position': 5, 'position_text': '5', 'points': 10.0, 'laps_completed': 57, 'status': 'Finished', 'time_millis': 5687713.0, 'time_text': '+50.977'}, {'race_id': '2023_1', 'driver_id': 'stroll', 'constructor_id': 'aston_martin', 'car_number': 18, 'grid_position': 8, 'final_position': 6, 'position_text': '6', 'points': 8.0, 'laps_completed': 57, 'status': 'Finished', 'time_millis': 5691238.0, 'time_text': '+54.502'}, {'race_id': '2023_1', 'driver_id': 'russell', 'constructor_id': 'mercedes', 'car_number': 63, 'grid_position': 6, 'final_position': 7, 'position_text': '7', 'points': 6.0, 'laps_completed': 57, 'status': 'Finished', 'time_millis': 5692609.0, 'time_text': '+55.873'}, {'race_id': '2023_1', 'driver_id': 'bottas', 'constructor_id': 'alfa', 'car_number': 77, 'grid_position': 12, 'final_position': 8, 'position_text': '8', 'points': 4.0, 'laps_completed': 57, 'status': 'Finished', 'time_millis': 5709383.0, 'time_text': '+1:12.647'}  ... displaying 10 of 180 total bound parameter sets ...  {'race_id': '2023_9', 'driver_id': 'tsunoda', 'constructor_id': 'alphatauri', 'car_number': 22, 'grid_position': 16, 'final_position': 19, 'position_text': '19', 'points': 0.0, 'laps_completed': 70, 'status': '+1 Lap', 'time_millis': None, 'time_text': None}, {'race_id': '2023_9', 'driver_id': 'hulkenberg', 'constructor_id': 'haas', 'car_number': 27, 'grid_position': 8, 'final_position': 20, 'position_text': 'R', 'points': 0.0, 'laps_completed': 12, 'status': 'Power loss', 'time_millis': None, 'time_text': None})]
(Background on this error at: https://sqlalche.me/e/14/gkpj)
[2025-06-04T08:30:31.701+0000] {logging_mixin.py:188} INFO - --- Résultat pour detailed_results.csv: ÉCHEC ---
[2025-06-04T08:30:31.702+0000] {logging_mixin.py:188} INFO - 
Valeur finale de overall_success avant le check: False
[2025-06-04T08:30:31.702+0000] {logging_mixin.py:188} INFO - overall_success est False, levée de ValueError.
[2025-06-04T08:30:31.702+0000] {taskinstance.py:441} INFO - ::group::Post task execution logs
[2025-06-04T08:30:31.702+0000] {taskinstance.py:2905} ERROR - Task failed with exception
Traceback (most recent call last):
  File "/home/airflow/.local/lib/python3.12/site-packages/airflow/models/taskinstance.py", line 465, in _execute_task
    result = _execute_callable(context=context, **execute_callable_kwargs)
             ^^^^^^^^^^^^^^^^^^^^^^^^^^^^^^^^^^^^^^^^^^^^^^^^^^^^^^^^^^^^^
  File "/home/airflow/.local/lib/python3.12/site-packages/airflow/models/taskinstance.py", line 432, in _execute_callable
    return execute_callable(context=context, **execute_callable_kwargs)
           ^^^^^^^^^^^^^^^^^^^^^^^^^^^^^^^^^^^^^^^^^^^^^^^^^^^^^^^^^^^^
  File "/home/airflow/.local/lib/python3.12/site-packages/airflow/models/baseoperator.py", line 401, in wrapper
    return func(self, *args, **kwargs)
           ^^^^^^^^^^^^^^^^^^^^^^^^^^^
  File "/home/airflow/.local/lib/python3.12/site-packages/airflow/operators/python.py", line 235, in execute
    return_value = self.execute_callable()
                   ^^^^^^^^^^^^^^^^^^^^^^^
  File "/home/airflow/.local/lib/python3.12/site-packages/airflow/operators/python.py", line 252, in execute_callable
    return self.python_callable(*self.op_args, **self.op_kwargs)
           ^^^^^^^^^^^^^^^^^^^^^^^^^^^^^^^^^^^^^^^^^^^^^^^^^^^^^
  File "/opt/airflow/plugins/etl_scripts/load_to_postgres.py", line 115, in load_all_processed_data_to_postgres
    raise ValueError(f"Un ou plusieurs chargements en base de données ont échoué pour l'année {year}.")
ValueError: Un ou plusieurs chargements en base de données ont échoué pour l'année 2023.
[2025-06-04T08:30:31.706+0000] {taskinstance.py:1206} INFO - Marking task as FAILED. dag_id=f1_data_extraction_pipeline, task_id=load_data_to_postgres, run_id=manual__2025-06-04T08:29:53+00:00, execution_date=20250604T082953, start_date=20250604T083031, end_date=20250604T083031
[2025-06-04T08:30:31.710+0000] {standard_task_runner.py:110} ERROR - Failed to execute job 15 for task load_data_to_postgres (Un ou plusieurs chargements en base de données ont échoué pour l'année 2023.; 652)
[2025-06-04T08:30:31.718+0000] {local_task_job_runner.py:240} INFO - Task exited with return code 1
[2025-06-04T08:30:31.725+0000] {taskinstance.py:3503} INFO - 0 downstream tasks scheduled from follow-on schedule check
[2025-06-04T08:30:31.725+0000] {local_task_job_runner.py:222} INFO - ::endgroup::
